Workbook

Sheet DATA 요약
G1: DL-G4547H
B2: [1] 카테고리별 요약(금액) | G2: CC670 | R2: (단위 : 백만원, TON)
B3: 금액 | D3: '2025.12 | E3: 25년 합계 (백만원) | F3: '2026.01 (실적) | G3: '2026.02 (실적) | H3: '2026.03 (실적) | I3: '2026.04 | J3: '2026.05 | K3: '2026.06 | L3: '2026.07 | M3: '2026.08 | N3: '2026.09 | O3: '2026.10 | P3: '2026.11 | Q3: '2026.12 | R3: 26년 합계 (백만원)
B4: 위생도기 | D4: =SUMIFS('통합 납품 계획'!$M$8:$M$6900,'통합 납품 계획'!$R$8:$R$6900,'DATA 요약'!$B$4,'통합 납품 계획'!$D$8:$D$6900,'DATA 요약'!D3) -> 0 | E4: =SUM(D4:D4) -> 0 | F4: 2987886732 | G4: 2966540550 | H4: 2069431326 | I4: =SUMIFS('통합 납품 계획'!$M$8:$M$6900,'통합 납품 계획'!$R$8:$R$6900,'DATA 요약'!$B$4,'통합 납품 계획'!$D$8:$D$6900,'DATA 요약'!I3) -> 3.4647979e+09 | J4: =SUMIFS('통합 납품 계획'!$M$8:$M$6900,'통합 납품 계획'!$R$8:$R$6900,'DATA 요약'!$B$4,'통합 납품 계획'!$D$8:$D$6900,'DATA 요약'!J3) -> 3.3051755e+09 | K4: =SUMIFS('통합 납품 계획'!$M$8:$M$6900,'통합 납품 계획'!$R$8:$R$6900,'DATA 요약'!$B$4,'통합 납품 계획'!$D$8:$D$6900,'DATA 요약'!K3) -> 2809544847 | L4: =SUMIFS('통합 납품 계획'!$M$8:$M$6900,'통합 납품 계획'!$R$8:$R$6900,'DATA 요약'!$B$4,'통합 납품 계획'!$D$8:$D$6900,'DATA 요약'!L3) -> 1128637432 | M4: =SUMIFS('통합 납품 계획'!$M$8:$M$6900,'통합 납품 계획'!$R$8:$R$6900,'DATA 요약'!$B$4,'통합 납품 계획'!$D$8:$D$6900,'DATA 요약'!M3) -> 2668153196 | N4: =SUMIFS('통합 납품 계획'!$M$8:$M$6900,'통합 납품 계획'!$R$8:$R$6900,'DATA 요약'!$B$4,'통합 납품 계획'!$D$8:$D$6900,'DATA 요약'!N3) -> 1.6377336e+09 | O4: =SUMIFS('통합 납품 계획'!$M$8:$M$6900,'통합 납품 계획'!$R$8:$R$6900,'DATA 요약'!$B$4,'통합 납품 계획'!$D$8:$D$6900,'DATA 요약'!O3) -> 1036977839 | P4: =SUMIFS('통합 납품 계획'!$M$8:$M$6900,'통합 납품 계획'!$R$8:$R$6900,'DATA 요약'!$B$4,'통합 납품 계획'!$D$8:$D$6900,'DATA 요약'!P3) -> 2.8955715e+08 | Q4: =SUMIFS('통합 납품 계획'!$M$8:$M$6900,'통합 납품 계획'!$R$8:$R$6900,'DATA 요약'!$B$4,'통합 납품 계획'!$D$8:$D$6900,'DATA 요약'!Q3) -> 1.9583856e+09 | R4: =SUM(F4:Q4) -> 2.6322822e+10
B5: OEM | D5: =SUMIFS('통합 납품 계획'!$M$8:$M$6900,'통합 납품 계획'!$R$8:$R$6900,'DATA 요약'!$B$5,'통합 납품 계획'!$D$8:$D$6900,'DATA 요약'!D3) -> 0 | E5: =SUM(D5:D5) -> 0 | F5: 568486209 | G5: 849732511 | H5: 464127510 | I5: =SUMIFS('통합 납품 계획'!$M$8:$M$6900,'통합 납품 계획'!$R$8:$R$6900,'DATA 요약'!$B$5,'통합 납품 계획'!$D$8:$D$6900,'DATA 요약'!I3) -> 489380985 | J5: =SUMIFS('통합 납품 계획'!$M$8:$M$6900,'통합 납품 계획'!$R$8:$R$6900,'DATA 요약'!$B$5,'통합 납품 계획'!$D$8:$D$6900,'DATA 요약'!J3) -> 3.0723334e+08 | K5: =SUMIFS('통합 납품 계획'!$M$8:$M$6900,'통합 납품 계획'!$R$8:$R$6900,'DATA 요약'!$B$5,'통합 납품 계획'!$D$8:$D$6900,'DATA 요약'!K3) -> 409453628 | L5: =SUMIFS('통합 납품 계획'!$M$8:$M$6900,'통합 납품 계획'!$R$8:$R$6900,'DATA 요약'!$B$5,'통합 납품 계획'!$D$8:$D$6900,'DATA 요약'!L3) -> 393526701 | M5: =SUMIFS('통합 납품 계획'!$M$8:$M$6900,'통합 납품 계획'!$R$8:$R$6900,'DATA 요약'!$B$5,'통합 납품 계획'!$D$8:$D$6900,'DATA 요약'!M3) -> 596881699 | N5: =SUMIFS('통합 납품 계획'!$M$8:$M$6900,'통합 납품 계획'!$R$8:$R$6900,'DATA 요약'!$B$5,'통합 납품 계획'!$D$8:$D$6900,'DATA 요약'!N3) -> 401478046 | O5: =SUMIFS('통합 납품 계획'!$M$8:$M$6900,'통합 납품 계획'!$R$8:$R$6900,'DATA 요약'!$B$5,'통합 납품 계획'!$D$8:$D$6900,'DATA 요약'!O3) -> 254901938 | P5: =SUMIFS('통합 납품 계획'!$M$8:$M$6900,'통합 납품 계획'!$R$8:$R$6900,'DATA 요약'!$B$5,'통합 납품 계획'!$D$8:$D$6900,'DATA 요약'!P3) -> 96989927 | Q5: =SUMIFS('통합 납품 계획'!$M$8:$M$6900,'통합 납품 계획'!$R$8:$R$6900,'DATA 요약'!$B$5,'통합 납품 계획'!$D$8:$D$6900,'DATA 요약'!Q3) -> 165081642 | R5: =SUM(F5:Q5) -> 4.9972741e+09
B6: 수전 | D6: =SUMIFS('통합 납품 계획'!$M$8:$M$6900,'통합 납품 계획'!$R$8:$R$6900,'DATA 요약'!$B$6,'통합 납품 계획'!$D$8:$D$6900,'DATA 요약'!D3) -> 0 | E6: =SUM(D6:D6) -> 0 | F6: 2069548978 | G6: 1654823958 | H6: 1773891556 | I6: =SUMIFS('통합 납품 계획'!$M$8:$M$6900,'통합 납품 계획'!$R$8:$R$6900,'DATA 요약'!$B$6,'통합 납품 계획'!$D$8:$D$6900,'DATA 요약'!I3) -> 1.0881141e+09 | J6: =SUMIFS('통합 납품 계획'!$M$8:$M$6900,'통합 납품 계획'!$R$8:$R$6900,'DATA 요약'!$B$6,'통합 납품 계획'!$D$8:$D$6900,'DATA 요약'!J3) -> 7.4727147e+08 | K6: =SUMIFS('통합 납품 계획'!$M$8:$M$6900,'통합 납품 계획'!$R$8:$R$6900,'DATA 요약'!$B$6,'통합 납품 계획'!$D$8:$D$6900,'DATA 요약'!K3) -> 1.0502271e+09 | L6: =SUMIFS('통합 납품 계획'!$M$8:$M$6900,'통합 납품 계획'!$R$8:$R$6900,'DATA 요약'!$B$6,'통합 납품 계획'!$D$8:$D$6900,'DATA 요약'!L3) -> 481087895 | M6: =SUMIFS('통합 납품 계획'!$M$8:$M$6900,'통합 납품 계획'!$R$8:$R$6900,'DATA 요약'!$B$6,'통합 납품 계획'!$D$8:$D$6900,'DATA 요약'!M3) -> 1868568288 | N6: =SUMIFS('통합 납품 계획'!$M$8:$M$6900,'통합 납품 계획'!$R$8:$R$6900,'DATA 요약'!$B$6,'통합 납품 계획'!$D$8:$D$6900,'DATA 요약'!N3) -> 410129320 | O6: =SUMIFS('통합 납품 계획'!$M$8:$M$6900,'통합 납품 계획'!$R$8:$R$6900,'DATA 요약'!$B$6,'통합 납품 계획'!$D$8:$D$6900,'DATA 요약'!O3) -> 739499532 | P6: =SUMIFS('통합 납품 계획'!$M$8:$M$6900,'통합 납품 계획'!$R$8:$R$6900,'DATA 요약'!$B$6,'통합 납품 계획'!$D$8:$D$6900,'DATA 요약'!P3) -> 866557766 | Q6: =SUMIFS('통합 납품 계획'!$M$8:$M$6900,'통합 납품 계획'!$R$8:$R$6900,'DATA 요약'!$B$6,'통합 납품 계획'!$D$8:$D$6900,'DATA 요약'!Q3) -> 7.115753e+08 | R6: =SUM(F6:Q6) -> 1.3461295e+10
B7: 비데 | D7: =SUMIFS('통합 납품 계획'!$M$8:$M$6900,'통합 납품 계획'!$R$8:$R$6900,'DATA 요약'!$B$7,'통합 납품 계획'!$D$8:$D$6900,'DATA 요약'!D3) -> 0 | E7: =SUM(D7:D7) -> 0 | F7: 472809600 | G7: 789031890 | H7: 128978630 | I7: =SUMIFS('통합 납품 계획'!$M$8:$M$6900,'통합 납품 계획'!$R$8:$R$6900,'DATA 요약'!$B$7,'통합 납품 계획'!$D$8:$D$6900,'DATA 요약'!I3) -> 1.1679181e+09 | J7: =SUMIFS('통합 납품 계획'!$M$8:$M$6900,'통합 납품 계획'!$R$8:$R$6900,'DATA 요약'!$B$7,'통합 납품 계획'!$D$8:$D$6900,'DATA 요약'!J3) -> 4.7140829e+08 | K7: =SUMIFS('통합 납품 계획'!$M$8:$M$6900,'통합 납품 계획'!$R$8:$R$6900,'DATA 요약'!$B$7,'통합 납품 계획'!$D$8:$D$6900,'DATA 요약'!K3) -> 3183760133 | L7: =SUMIFS('통합 납품 계획'!$M$8:$M$6900,'통합 납품 계획'!$R$8:$R$6900,'DATA 요약'!$B$7,'통합 납품 계획'!$D$8:$D$6900,'DATA 요약'!L3) -> 67248750 | M7: =SUMIFS('통합 납품 계획'!$M$8:$M$6900,'통합 납품 계획'!$R$8:$R$6900,'DATA 요약'!$B$7,'통합 납품 계획'!$D$8:$D$6900,'DATA 요약'!M3) -> 251999598 | N7: =SUMIFS('통합 납품 계획'!$M$8:$M$6900,'통합 납품 계획'!$R$8:$R$6900,'DATA 요약'!$B$7,'통합 납품 계획'!$D$8:$D$6900,'DATA 요약'!N3) -> 2.1406393e+08 | O7: =SUMIFS('통합 납품 계획'!$M$8:$M$6900,'통합 납품 계획'!$R$8:$R$6900,'DATA 요약'!$B$7,'통합 납품 계획'!$D$8:$D$6900,'DATA 요약'!O3) -> 256554506 | P7: =SUMIFS('통합 납품 계획'!$M$8:$M$6900,'통합 납품 계획'!$R$8:$R$6900,'DATA 요약'!$B$7,'통합 납품 계획'!$D$8:$D$6900,'DATA 요약'!P3) -> 99846996 | Q7: =SUMIFS('통합 납품 계획'!$M$8:$M$6900,'통합 납품 계획'!$R$8:$R$6900,'DATA 요약'!$B$7,'통합 납품 계획'!$D$8:$D$6900,'DATA 요약'!Q3) -> 623130714 | R7: =SUM(F7:Q7) -> 7.7267511e+09
B8: 상품 | C8: (반다리, 하부장) | D8: =SUMIFS('통합 납품 계획'!$M$8:$M$6900,'통합 납품 계획'!$R$8:$R$6900,'DATA 요약'!$B$8,'통합 납품 계획'!$D$8:$D$6900,'DATA 요약'!D3) -> 0 | E8: =SUM(D8:D8) -> 0 | F8: 446800000 | G8: 141286000 | H8: 68140000 | I8: =SUMIFS('통합 납품 계획'!$M$8:$M$6900,'통합 납품 계획'!$R$8:$R$6900,'DATA 요약'!$B$8,'통합 납품 계획'!$D$8:$D$6900,'DATA 요약'!I3) -> 166952777 | J8: =SUMIFS('통합 납품 계획'!$M$8:$M$6900,'통합 납품 계획'!$R$8:$R$6900,'DATA 요약'!$B$8,'통합 납품 계획'!$D$8:$D$6900,'DATA 요약'!J3) -> 3.0853367e+08 | K8: =SUMIFS('통합 납품 계획'!$M$8:$M$6900,'통합 납품 계획'!$R$8:$R$6900,'DATA 요약'!$B$8,'통합 납품 계획'!$D$8:$D$6900,'DATA 요약'!K3) -> 45841920 | L8: =SUMIFS('통합 납품 계획'!$M$8:$M$6900,'통합 납품 계획'!$R$8:$R$6900,'DATA 요약'!$B$8,'통합 납품 계획'!$D$8:$D$6900,'DATA 요약'!L3) -> 7383684 | M8: =SUMIFS('통합 납품 계획'!$M$8:$M$6900,'통합 납품 계획'!$R$8:$R$6900,'DATA 요약'!$B$8,'통합 납품 계획'!$D$8:$D$6900,'DATA 요약'!M3) -> 750672204 | N8: =SUMIFS('통합 납품 계획'!$M$8:$M$6900,'통합 납품 계획'!$R$8:$R$6900,'DATA 요약'!$B$8,'통합 납품 계획'!$D$8:$D$6900,'DATA 요약'!N3) -> 4.4526831e+08 | O8: =SUMIFS('통합 납품 계획'!$M$8:$M$6900,'통합 납품 계획'!$R$8:$R$6900,'DATA 요약'!$B$8,'통합 납품 계획'!$D$8:$D$6900,'DATA 요약'!O3) -> 35861764 | P8: =SUMIFS('통합 납품 계획'!$M$8:$M$6900,'통합 납품 계획'!$R$8:$R$6900,'DATA 요약'!$B$8,'통합 납품 계획'!$D$8:$D$6900,'DATA 요약'!P3) -> 0 | Q8: =SUMIFS('통합 납품 계획'!$M$8:$M$6900,'통합 납품 계획'!$R$8:$R$6900,'DATA 요약'!$B$8,'통합 납품 계획'!$D$8:$D$6900,'DATA 요약'!Q3) -> 99418984 | R8: =SUM(F8:Q8) -> 2.5161593e+09
B9: 상품 | C9: (양부속, 트랩) | D9: =(D4+D5)*17% -> 0 | E9: =SUM(D9:D9) -> 0 | F9: 642072925 | G9: 821977990 | H9: 501540864 | I9: =(I4+I5)*20% -> 7.9083577e+08 | J9: =(J4+J5)*20% -> 7.2248177e+08 | K9: =(K4+K5)*20% -> 643799695 | L9: =(L4+L5)*20% -> 3.0443283e+08 | M9: =(M4+M5)*20% -> 653006979 | N9: =(N4+N5)*20% -> 4.0784232e+08 | O9: =(O4+O5)*20% -> 2.5837596e+08 | P9: =(P4+P5)*20% -> 77309415 | Q9: =(Q4+Q5)*20% -> 4.2469345e+08 | R9: =SUM(F9:Q9) -> 6.24837e+09
B10: 합계 | D10: =SUM(D4:D9) -> 0 | E10: =SUM(D10:D10) -> 0 | F10: =SUM(F4:F9) -> 7187604444 | G10: =SUM(G4:G9) -> 7223392899 | H10: =SUM(H4:H9) -> 5006109886 | I10: =SUM(I4:I9) -> 7.1679996e+09 | J10: =SUM(J4:J9) -> 5.862104e+09 | K10: =SUM(K4:K9) -> 8.1426273e+09 | L10: =SUM(L4:L9) -> 2.3823173e+09 | M10: =SUM(M4:M9) -> 6789281964 | ... Q10: =SUM(Q4:Q9) -> 3.9822857e+09 | R10: =SUM(F10:Q10) -> 6.1272671e+10
B11: [2] 카테고리별 요약(중량) | G11: BFL410
B12: 중량 | D12: '2025.12 | E12: 25년 합계 (TON) | F12: '2026.01 (실적) | G12: '2026.02 (실적) | H12: '2026.03 (실적) | I12: '2026.04 | J12: '2026.05 | K12: '2026.06 | L12: '2026.07 | M12: '2026.08 | N12: '2026.09 | O12: '2026.10 | P12: '2026.11 | Q12: '2026.12 | R12: 26년 합계 (TON)
B13: 위생도기 | D13: =SUMIFS('통합 납품 계획'!$L$8:$L$6900,'통합 납품 계획'!$R$8:$R$6900,'DATA 요약'!$B$4,'통합 납품 계획'!$D$8:$D$6900,'DATA 요약'!D12) -> 0 | E13: =SUM(D13:D13) -> 0 | F13: 642 | G13: 674 | H13: 454 | I13: =SUMIFS('통합 납품 계획'!$L$8:$L$6900,'통합 납품 계획'!$R$8:$R$6900,'DATA 요약'!$B$4,'통합 납품 계획'!$D$8:$D$6900,'DATA 요약'!I12) -> 656.4279 | J13: =SUMIFS('통합 납품 계획'!$L$8:$L$6900,'통합 납품 계획'!$R$8:$R$6900,'DATA 요약'!$B$4,'통합 납품 계획'!$D$8:$D$6900,'DATA 요약'!J12) -> 647.8392 | K13: =SUMIFS('통합 납품 계획'!$L$8:$L$6900,'통합 납품 계획'!$R$8:$R$6900,'DATA 요약'!$B$4,'통합 납품 계획'!$D$8:$D$6900,'DATA 요약'!K12) -> 585.4587 | L13: =SUMIFS('통합 납품 계획'!$L$8:$L$6900,'통합 납품 계획'!$R$8:$R$6900,'DATA 요약'!$B$4,'통합 납품 계획'!$D$8:$D$6900,'DATA 요약'!L12) -> 242.2574 | M13: =SUMIFS('통합 납품 계획'!$L$8:$L$6900,'통합 납품 계획'!$R$8:$R$6900,'DATA 요약'!$B$4,'통합 납품 계획'!$D$8:$D$6900,'DATA 요약'!M12) -> 578.5037 | N13: =SUMIFS('통합 납품 계획'!$L$8:$L$6900,'통합 납품 계획'!$R$8:$R$6900,'DATA 요약'!$B$4,'통합 납품 계획'!$D$8:$D$6900,'DATA 요약'!N12) -> 289.7372 | O13: =SUMIFS('통합 납품 계획'!$L$8:$L$6900,'통합 납품 계획'!$R$8:$R$6900,'DATA 요약'!$B$4,'통합 납품 계획'!$D$8:$D$6900,'DATA 요약'!O12) -> 196.5352 | P13: =SUMIFS('통합 납품 계획'!$L$8:$L$6900,'통합 납품 계획'!$R$8:$R$6900,'DATA 요약'!$B$4,'통합 납품 계획'!$D$8:$D$6900,'DATA 요약'!P12) -> 48.8594 | Q13: =SUMIFS('통합 납품 계획'!$L$8:$L$6900,'통합 납품 계획'!$R$8:$R$6900,'DATA 요약'!$B$4,'통합 납품 계획'!$D$8:$D$6900,'DATA 요약'!Q12) -> 415.4709 | R13: =SUM(F13:Q13) -> 5431.0896
B14: OEM | D14: =SUMIFS('통합 납품 계획'!$L$8:$L$6900,'통합 납품 계획'!$R$8:$R$6900,'DATA 요약'!$B$5,'통합 납품 계획'!$D$8:$D$6900,'DATA 요약'!D12) -> 0 | E14: =SUM(D14:D14) -> 0 | F14: 223 | G14: 385 | H14: 168 | I14: =SUMIFS('통합 납품 계획'!$L$8:$L$6900,'통합 납품 계획'!$R$8:$R$6900,'DATA 요약'!$B$5,'통합 납품 계획'!$D$8:$D$6900,'DATA 요약'!I12) -> 160.6523 | J14: =SUMIFS('통합 납품 계획'!$L$8:$L$6900,'통합 납품 계획'!$R$8:$R$6900,'DATA 요약'!$B$5,'통합 납품 계획'!$D$8:$D$6900,'DATA 요약'!J12) -> 123.8615 | K14: =SUMIFS('통합 납품 계획'!$L$8:$L$6900,'통합 납품 계획'!$R$8:$R$6900,'DATA 요약'!$B$5,'통합 납품 계획'!$D$8:$D$6900,'DATA 요약'!K12) -> 178.9495 | L14: =SUMIFS('통합 납품 계획'!$L$8:$L$6900,'통합 납품 계획'!$R$8:$R$6900,'DATA 요약'!$B$5,'통합 납품 계획'!$D$8:$D$6900,'DATA 요약'!L12) -> 185.649 | M14: =SUMIFS('통합 납품 계획'!$L$8:$L$6900,'통합 납품 계획'!$R$8:$R$6900,'DATA 요약'!$B$5,'통합 납품 계획'!$D$8:$D$6900,'DATA 요약'!M12) -> 253.029 | N14: =SUMIFS('통합 납품 계획'!$L$8:$L$6900,'통합 납품 계획'!$R$8:$R$6900,'DATA 요약'!$B$5,'통합 납품 계획'!$D$8:$D$6900,'DATA 요약'!N12) -> 157.5122 | O14: =SUMIFS('통합 납품 계획'!$L$8:$L$6900,'통합 납품 계획'!$R$8:$R$6900,'DATA 요약'!$B$5,'통합 납품 계획'!$D$8:$D$6900,'DATA 요약'!O12) -> 112.5321 | P14: =SUMIFS('통합 납품 계획'!$L$8:$L$6900,'통합 납품 계획'!$R$8:$R$6900,'DATA 요약'!$B$5,'통합 납품 계획'!$D$8:$D$6900,'DATA 요약'!P12) -> 69.7138 | Q14: =SUMIFS('통합 납품 계획'!$L$8:$L$6900,'통합 납품 계획'!$R$8:$R$6900,'DATA 요약'!$B$5,'통합 납품 계획'!$D$8:$D$6900,'DATA 요약'!Q12) -> 73.142 | R14: =SUM(F14:Q14) -> 2091.0414
B15: 합계 | D15: =SUM(D13:D14) -> 0 | E15: =SUM(D15:D15) -> 0 | F15: =SUM(F13:F14) -> 865 | G15: =SUM(G13:G14) -> 1059 | H15: =SUM(H13:H14) -> 622 | I15: =SUM(I13:I14) -> 817.0802 | J15: =SUM(J13:J14) -> 771.7007 | K15: =SUM(K13:K14) -> 764.4082 | L15: =SUM(L13:L14) -> 427.9064 | M15: =SUM(M13:M14) -> 831.5327 | ... Q15: =SUM(Q13:Q14) -> 488.6129 | R15: =SUM(F15:Q15) -> 7522.131
G16: DL-P4202
B17: [3] 품번 요약(노란음영 원하는 품번 입력)
G18: 품목 | Q18: (단위 : EA, 백만원)
B19: 품번 | C19: 납품수량 | D19: '2025.12 | E19: 25년 합계 | F19: '2026.01 | G19: '2026.02 | H19: '2026.03 | I19: '2026.04 | J19: '2026.05 | K19: '2026.06 | L19: '2026.07 | M19: '2026.08 | N19: '2026.09 | O19: '2026.10 | P19: '2026.11 | Q19: '2026.12 | R19: 26년 합계
B20: CLR339 | C20: 수량 | D20: =SUMIFS('통합 납품 계획'!$H$8:$H$6900,'통합 납품 계획'!$F$8:$F$6900,'DATA 요약'!$B$20,'통합 납품 계획'!$D$8:$D$6900,'DATA 요약'!D19) -> 0 | E20: =SUM(D20:D20) -> 0 | F20: =SUMIFS('통합 납품 계획'!$H$8:$H$6900,'통합 납품 계획'!$F$8:$F$6900,'DATA 요약'!$B$20,'통합 납품 계획'!$D$8:$D$6900,'DATA 요약'!F19) -> 0 | G20: =SUMIFS('통합 납품 계획'!$H$8:$H$6900,'통합 납품 계획'!$F$8:$F$6900,'DATA 요약'!$B$20,'통합 납품 계획'!$D$8:$D$6900,'DATA 요약'!G19) -> 0 | H20: =SUMIFS('통합 납품 계획'!$H$8:$H$6900,'통합 납품 계획'!$F$8:$F$6900,'DATA 요약'!$B$20,'통합 납품 계획'!$D$8:$D$6900,'DATA 요약'!H19) -> 0 | I20: =SUMIFS('통합 납품 계획'!$H$8:$H$6900,'통합 납품 계획'!$F$8:$F$6900,'DATA 요약'!$B$20,'통합 납품 계획'!$D$8:$D$6900,'DATA 요약'!I19) -> 192 | J20: =SUMIFS('통합 납품 계획'!$H$8:$H$6900,'통합 납품 계획'!$F$8:$F$6900,'DATA 요약'!$B$20,'통합 납품 계획'!$D$8:$D$6900,'DATA 요약'!J19) -> 949 | K20: =SUMIFS('통합 납품 계획'!$H$8:$H$6900,'통합 납품 계획'!$F$8:$F$6900,'DATA 요약'!$B$20,'통합 납품 계획'!$D$8:$D$6900,'DATA 요약'!K19) -> 0 | L20: =SUMIFS('통합 납품 계획'!$H$8:$H$6900,'통합 납품 계획'!$F$8:$F$6900,'DATA 요약'!$B$20,'통합 납품 계획'!$D$8:$D$6900,'DATA 요약'!L19) -> 0 | M20: =SUMIFS('통합 납품 계획'!$H$8:$H$6900,'통합 납품 계획'!$F$8:$F$6900,'DATA 요약'!$B$20,'통합 납품 계획'!$D$8:$D$6900,'DATA 요약'!M19) -> 2024 | ... Q20: =SUMIFS('통합 납품 계획'!$H$8:$H$6900,'통합 납품 계획'!$F$8:$F$6900,'DATA 요약'!$B$20,'통합 납품 계획'!$D$8:$D$6900,'DATA 요약'!Q19) -> 0 | R20: =SUM(F20:Q20) -> 3828
C21: 금액 | D21: =SUMIFS('통합 납품 계획'!$M$8:$M$6900,'통합 납품 계획'!$F$8:$F$6900,'DATA 요약'!$B$20,'통합 납품 계획'!$D$8:$D$6900,'DATA 요약'!D19) -> 0 | E21: =SUM(D21:D21) -> 0 | F21: =SUMIFS('통합 납품 계획'!$M$8:$M$6900,'통합 납품 계획'!$F$8:$F$6900,'DATA 요약'!$B$20,'통합 납품 계획'!$D$8:$D$6900,'DATA 요약'!F19) -> 0 | G21: =SUMIFS('통합 납품 계획'!$M$8:$M$6900,'통합 납품 계획'!$F$8:$F$6900,'DATA 요약'!$B$20,'통합 납품 계획'!$D$8:$D$6900,'DATA 요약'!G19) -> 0 | H21: =SUMIFS('통합 납품 계획'!$M$8:$M$6900,'통합 납품 계획'!$F$8:$F$6900,'DATA 요약'!$B$20,'통합 납품 계획'!$D$8:$D$6900,'DATA 요약'!H19) -> 0 | I21: =SUMIFS('통합 납품 계획'!$M$8:$M$6900,'통합 납품 계획'!$F$8:$F$6900,'DATA 요약'!$B$20,'통합 납품 계획'!$D$8:$D$6900,'DATA 요약'!I19) -> 11379072 | J21: =SUMIFS('통합 납품 계획'!$M$8:$M$6900,'통합 납품 계획'!$F$8:$F$6900,'DATA 요약'!$B$20,'통합 납품 계획'!$D$8:$D$6900,'DATA 요약'!J19) -> 56243434 | K21: =SUMIFS('통합 납품 계획'!$M$8:$M$6900,'통합 납품 계획'!$F$8:$F$6900,'DATA 요약'!$B$20,'통합 납품 계획'!$D$8:$D$6900,'DATA 요약'!K19) -> 0 | L21: =SUMIFS('통합 납품 계획'!$M$8:$M$6900,'통합 납품 계획'!$F$8:$F$6900,'DATA 요약'!$B$20,'통합 납품 계획'!$D$8:$D$6900,'DATA 요약'!L19) -> 0 | M21: =SUMIFS('통합 납품 계획'!$M$8:$M$6900,'통합 납품 계획'!$F$8:$F$6900,'DATA 요약'!$B$20,'통합 납품 계획'!$D$8:$D$6900,'DATA 요약'!M19) -> 119954384 | ... Q21: =SUMIFS('통합 납품 계획'!$M$8:$M$6900,'통합 납품 계획'!$F$8:$F$6900,'DATA 요약'!$B$20,'통합 납품 계획'!$D$8:$D$6900,'DATA 요약'!Q19) -> 0 | R21: =SUM(F21:Q21) -> 226870248
G22: DL-S4516
B23: [4] 품목 요약(노란음영 원하는 품목 입력) | G23: DL-B9119HRS3
G24: DL-P4014 | Q24: (단위 : EA, 백만원)
B25: 품번 | C25: 납품수량 | D25: '2025.12 | E25: 25년 합계 | F25: '2026.01 | G25: '2026.02 | H25: '2026.03 | I25: '2026.04 | J25: '2026.05 | K25: '2026.06 | L25: '2026.07 | M25: '2026.08 | N25: '2026.09 | O25: '2026.10 | P25: '2026.11 | Q25: '2026.12 | R25: 26년 합계
B26: 일체형양변기 | C26: 수량 | D26: =SUMIFS('통합 납품 계획'!$H$8:$H$6900,'통합 납품 계획'!$Q$8:$Q$6900,'DATA 요약'!$B$26,'통합 납품 계획'!$D$8:$D$6900,'DATA 요약'!D25) -> 0 | E26: =SUM(D26:D26) -> 0 | F26: =SUMIFS('통합 납품 계획'!$H$8:$H$6900,'통합 납품 계획'!$Q$8:$Q$6900,'DATA 요약'!$B$26,'통합 납품 계획'!$D$8:$D$6900,'DATA 요약'!F25) -> 0 | G26: =SUMIFS('통합 납품 계획'!$H$8:$H$6900,'통합 납품 계획'!$Q$8:$Q$6900,'DATA 요약'!$B$26,'통합 납품 계획'!$D$8:$D$6900,'DATA 요약'!G25) -> 0 | H26: =SUMIFS('통합 납품 계획'!$H$8:$H$6900,'통합 납품 계획'!$Q$8:$Q$6900,'DATA 요약'!$B$26,'통합 납품 계획'!$D$8:$D$6900,'DATA 요약'!H25) -> 0 | I26: =SUMIFS('통합 납품 계획'!$H$8:$H$6900,'통합 납품 계획'!$Q$8:$Q$6900,'DATA 요약'!$B$26,'통합 납품 계획'!$D$8:$D$6900,'DATA 요약'!I25) -> 5190 | J26: =SUMIFS('통합 납품 계획'!$H$8:$H$6900,'통합 납품 계획'!$Q$8:$Q$6900,'DATA 요약'!$B$26,'통합 납품 계획'!$D$8:$D$6900,'DATA 요약'!J25) -> 3184 | K26: =SUMIFS('통합 납품 계획'!$H$8:$H$6900,'통합 납품 계획'!$Q$8:$Q$6900,'DATA 요약'!$B$26,'통합 납품 계획'!$D$8:$D$6900,'DATA 요약'!K25) -> 2073 | L26: =SUMIFS('통합 납품 계획'!$H$8:$H$6900,'통합 납품 계획'!$Q$8:$Q$6900,'DATA 요약'!$B$26,'통합 납품 계획'!$D$8:$D$6900,'DATA 요약'!L25) -> 322 | M26: =SUMIFS('통합 납품 계획'!$H$8:$H$6900,'통합 납품 계획'!$Q$8:$Q$6900,'DATA 요약'!$B$26,'통합 납품 계획'!$D$8:$D$6900,'DATA 요약'!M25) -> 1342 | ... Q26: =SUMIFS('통합 납품 계획'!$H$8:$H$6900,'통합 납품 계획'!$Q$8:$Q$6900,'DATA 요약'!$B$26,'통합 납품 계획'!$D$8:$D$6900,'DATA 요약'!Q25) -> 1381 | R26: =SUM(F26:Q26) -> 19733
C27: 금액 | D27: =SUMIFS('통합 납품 계획'!$M$8:$M$6900,'통합 납품 계획'!$Q$8:$Q$6900,'DATA 요약'!$B$26,'통합 납품 계획'!$D$8:$D$6900,'DATA 요약'!D25) -> 0 | E27: =SUM(D27:D27) -> 0 | F27: =SUMIFS('통합 납품 계획'!$M$8:$M$6900,'통합 납품 계획'!$Q$8:$Q$6900,'DATA 요약'!$B$26,'통합 납품 계획'!$D$8:$D$6900,'DATA 요약'!F25) -> 0 | G27: =SUMIFS('통합 납품 계획'!$M$8:$M$6900,'통합 납품 계획'!$Q$8:$Q$6900,'DATA 요약'!$B$26,'통합 납품 계획'!$D$8:$D$6900,'DATA 요약'!G25) -> 0 | H27: =SUMIFS('통합 납품 계획'!$M$8:$M$6900,'통합 납품 계획'!$Q$8:$Q$6900,'DATA 요약'!$B$26,'통합 납품 계획'!$D$8:$D$6900,'DATA 요약'!H25) -> 0 | I27: =SUMIFS('통합 납품 계획'!$M$8:$M$6900,'통합 납품 계획'!$Q$8:$Q$6900,'DATA 요약'!$B$26,'통합 납품 계획'!$D$8:$D$6900,'DATA 요약'!I25) -> 1.1810968e+09 | J27: =SUMIFS('통합 납품 계획'!$M$8:$M$6900,'통합 납품 계획'!$Q$8:$Q$6900,'DATA 요약'!$B$26,'통합 납품 계획'!$D$8:$D$6900,'DATA 요약'!J25) -> 7.5474113e+08 | K27: =SUMIFS('통합 납품 계획'!$M$8:$M$6900,'통합 납품 계획'!$Q$8:$Q$6900,'DATA 요약'!$B$26,'통합 납품 계획'!$D$8:$D$6900,'DATA 요약'!K25) -> 356018520 | L27: =SUMIFS('통합 납품 계획'!$M$8:$M$6900,'통합 납품 계획'!$Q$8:$Q$6900,'DATA 요약'!$B$26,'통합 납품 계획'!$D$8:$D$6900,'DATA 요약'!L25) -> 51799842 | M27: =SUMIFS('통합 납품 계획'!$M$8:$M$6900,'통합 납품 계획'!$Q$8:$Q$6900,'DATA 요약'!$B$26,'통합 납품 계획'!$D$8:$D$6900,'DATA 요약'!M25) -> 219616676 | ... Q27: =SUMIFS('통합 납품 계획'!$M$8:$M$6900,'통합 납품 계획'!$Q$8:$Q$6900,'DATA 요약'!$B$26,'통합 납품 계획'!$D$8:$D$6900,'DATA 요약'!Q25) -> 250285134 | R27: =SUM(F27:Q27) -> 4.1220913e+09
G28: DL-P4201 | N28: 레인샤워
G29: DL-G4541SC | N29: 샤워헤드
G30: DL-G4545SC | N30: 매립형샤워
G31: DL-K6219 | N31: 기타수전
G32: CC5000PWFT | N32: 스프레이건
G33: CC660NN | N33: 가로꼭지
G34: CL336W | N34: 싱크수전
G35: CL760 | N35: 일체형양변기
G36: DL-B3213 | N36: 세면수전
G37: DL-B7010 | N37: 투피스
G38: DL-K3015 | N38: 바트라
G39: DL-A9081 | N39: 슬라이드바
... G72: CL347 | N72: 온열시트
...

Sheet 통합 납품 계획
A1: 리테일부문 납품 계획 | C1: (단위 : 백만원) | D1: '2026.04 | E1: '2026.05 | F1: '2026.06 | H1: (단위 : 백만원) | I1: 직납 | J1: 대리점 | K1: 합계
C2: 위생도기 | D2: =SUMIFS($M$8:$M$6900,$R$8:$R$6900,C2,$D$8:$D$6900,$D$1) -> 3.4647979e+09 | E2: =SUMIFS($M$8:$M$6900,$R$8:$R$6900,C2,$D$8:$D$6900,$E$1) -> 3.3051755e+09 | F2: =SUMIFS($M$8:$M$6900,$R$8:$R$6900,C2,$D$8:$D$6900,$F$1) -> 2809544847 | H2: 위생도기 | I2: 6083121027 | J2: =K2-I2 -> 12014269505 | K2: 18097390532
A3: ※2632 ~ 2656행 : 리테일부문 납품 추가분 | C3: OEM | D3: =SUMIFS($M$8:$M$6900,$R$8:$R$6900,C3,$D$8:$D$6900,$D$1) -> 489380985 | E3: =SUMIFS($M$8:$M$6900,$R$8:$R$6900,C3,$D$8:$D$6900,$E$1) -> 3.0723334e+08 | F3: =SUMIFS($M$8:$M$6900,$R$8:$R$6900,C3,$D$8:$D$6900,$F$1) -> 409453628 | H3: OEM | I3: 674700360 | J3: =K3-I3 -> 3640556577 | K3: 4315256937
A4: ※2657 ~ 2962행 : 프로젝트부문 3월 SPEC 추가분 | C4: 수전 | D4: =SUMIFS($M$8:$M$6900,$R$8:$R$6900,C4,$D$8:$D$6900,$D$1) -> 1.0881141e+09 | E4: =SUMIFS($M$8:$M$6900,$R$8:$R$6900,C4,$D$8:$D$6900,$E$1) -> 7.4727147e+08 | F4: =SUMIFS($M$8:$M$6900,$R$8:$R$6900,C4,$D$8:$D$6900,$F$1) -> 1.0502271e+09 | H4: 수전 | I4: 5023252826 | J4: =K4-I4 -> 3809779439 | K4: 8833032265
C5: 비데 | D5: =SUMIFS($M$8:$M$6900,$R$8:$R$6900,C5,$D$8:$D$6900,$D$1) -> 1.1679181e+09 | E5: =SUMIFS($M$8:$M$6900,$R$8:$R$6900,C5,$D$8:$D$6900,$E$1) -> 4.7140829e+08 | F5: =SUMIFS($M$8:$M$6900,$R$8:$R$6900,C5,$D$8:$D$6900,$F$1) -> 3183760133 | H5: 비데 | I5: 3981904747 | J5: =K5-I5 -> 3840761675 | K5: 7822666422
C6: 상품 | D6: =SUMIFS($M$8:$M$6900,$R$8:$R$6900,C6,$D$8:$D$6900,$D$1)+((D2+D3)*0.2) -> 9.5778855e+08 | E6: =SUMIFS($M$8:$M$6900,$R$8:$R$6900,C6,$D$8:$D$6900,$E$1)+((E2+E3)*0.2) -> 1.0310154e+09 | F6: =SUMIFS($M$8:$M$6900,$R$8:$R$6900,C6,$D$8:$D$6900,$F$1)+((F2+F3)*0.2) -> 6.8964161e+08 | H6: 상품 | I6: =1984839735+((I2+I3)*0.2) -> 3.336404e+09 | J6: =K6-I6 -> 3.8183053e+09 | K6: =2672179806+((K2+K3)*0.2) -> 7.1547093e+09
A7: 46119 | C7: 합계 | D7: =SUM(D2:D6) -> 7.1679996e+09 | E7: =SUM(E2:E6) -> 5.862104e+09 | F7: =SUM(F2:F6) -> 8.1426273e+09 | H7: 합계 | I7: =SUBTOTAL(9,I2:I6) -> 1.9099383e+10 | J7: =SUBTOTAL(9,J2:J6) -> 2.7123672e+10 | K7: =SUBTOTAL(9,K2:K6) -> 4.6223055e+10 | L7: =SUBTOTAL(9,L9:L4183) -> 14288.982 | M7: =SUBTOTAL(9,M9:M4183) -> 1.0511377e+11 | S7: (단위 : EA,원)
A8: 건설회사 | B8: 현장명 | C8: 대리점 | D8: 납품예정 | E8: 입주예정 | F8: 품목 | G8: 색상 | H8: 수량 | I8: 대리점가 | J8: 중량(KG) | K8: 총무게(KG) | L8: 총무게(TON) | M8: 금액 | N8: 특수사양 | O8: 비고 | P8: 담당자 | Q8: 품목 | R8: 구분 | S8: SPEC담당
A9: 코오롱건설 | B9: 대전 봉명 주상복합 | C9: 홈센타홀딩스 | D9: '2027.10 | F9: CC267 | H9: 1382 | I9: 191082 | J9: 34.6 | K9: =IFERROR(J9*H9,"0") -> 47817.2 | L9: =IFERROR(K9/1000,"0") -> 47.8172 | M9: =I9*H9 -> 264075324 | P9: 조동욱 | Q9: 원피스 | R9: 위생도기 | S9: 박기진
A10: 코오롱건설 | B10: 대전 봉명 주상복합 | C10: 홈센타홀딩스 | D10: '2027.10 | F10: CLL758D | H10: 691 | I10: 63889 | J10: 13.3 | K10: =IFERROR(J10*H10,"0") -> 9190.3 | L10: =IFERROR(K10/1000,"0") -> 9.1903 | M10: =I10*H10 -> 44147299 | P10: 조동욱 | Q10: 벽붙이세면기 | R10: 위생도기 | S10: 박기진
A11: 코오롱건설 | B11: 대전 봉명 주상복합 | C11: 홈센타홀딩스 | D11: '2027.10 | F11: CLL336S | H11: 691 | I11: 62283 | J11: 11.8 | K11: =IFERROR(J11*H11,"0") -> 8153.8 | L11: =IFERROR(K11/1000,"0") -> 8.1538 | M11: =I11*H11 -> 43037553 | P11: 조동욱 | Q11: 벽붙이세면기 | R11: 위생도기 | S11: 박기진
A12: 코오롱건설 | B12: 권선6구역 래미안 매교역 팰루시드(1차 납품) | C12: 홈센타홀딩스 | D12: '2026.06 | F12: TSC416D | H12: 200 | I12: 11500 | J12: 0 | K12: =IFERROR(J12*H12,"0") -> 0 | L12: =IFERROR(K12/1000,"0") -> 0 | M12: =I12*H12 -> 2300000 | P12: 조동욱 | Q12: 시트 | R12: 상품 | S12: 박기진
A13: 코오롱건설 | B13: 권선6구역 래미안 매교역 팰루시드(1차 납품) | C13: 홈센타홀딩스 | D13: '2026.04 | F13: CLR358 | H13: 389 | I13: 90400 | J13: 21 | K13: =IFERROR(J13*H13,"0") -> 8169 | L13: =IFERROR(K13/1000,"0") -> 8.169 | M13: =I13*H13 -> 35165600 | P13: 조동욱 | Q13: 일체형세면기 | R13: 위생도기 | S13: 박기진
A14: 코오롱건설 | B14: 권선6구역 래미안 매교역 팰루시드(막차 납품) | C14: 홈센타홀딩스 | D14: '2026.04 | F14: CC660NLT | H14: 384 | I14: 158000 | J14: 27 | K14: =IFERROR(J14*H14,"0") -> 10368 | L14: =IFERROR(K14/1000,"0") -> 10.368 | M14: =I14*H14 -> 60672000 | P14: 조동욱 | Q14: 일체형양변기 | R14: 위생도기 | S14: 박기진
A15: 코오롱건설 | B15: 권선6구역 래미안 매교역 팰루시드(막차 납품) | C15: 홈센타홀딩스 | D15: '2026.06 | F15: TSC416D | H15: 235 | I15: 11500 | J15: 0 | K15: =IFERROR(J15*H15,"0") -> 0 | L15: =IFERROR(K15/1000,"0") -> 0 | M15: =I15*H15 -> 2702500 | P15: 조동욱 | Q15: 시트 | R15: 상품 | S15: 박기진
A16: 코오롱건설 | B16: 권선6구역 래미안 매교역 팰루시드(막차 납품) | C16: 홈센타홀딩스 | D16: '2026.04 | F16: CC750 | H16: 187 | I16: 140980 | J16: 20 | K16: =IFERROR(J16*H16,"0") -> 3740 | L16: =IFERROR(K16/1000,"0") -> 3.74 | M16: =I16*H16 -> 26363260 | P16: 조동욱 | Q16: 투피스 | R16: 위생도기 | S16: 박기진
A17: 코오롱건설 | B17: 권선6구역 래미안 매교역 팰루시드(막차 납품) | C17: 홈센타홀딩스 | D17: '2026.04 | F17: CLR358 | H17: 598 | I17: 90400 | J17: 21 | K17: =IFERROR(J17*H17,"0") -> 12558 | L17: =IFERROR(K17/1000,"0") -> 12.558 | M17: =I17*H17 -> 54059200 | P17: 조동욱 | Q17: 일체형세면기 | R17: 위생도기 | S17: 박기진
A18: 삼성물산 | B18: 권선6구역 래미안 매교역 팰루시드(1차 납품) | C18: 케이씨씨글라스 | D18: '2026.04 | F18: TSC416D | H18: 200 | I18: 11649 | J18: 0 | K18: =IFERROR(J18*H18,"0") -> 0 | L18: =IFERROR(K18/1000,"0") -> 0 | M18: =I18*H18 -> 2329800 | P18: 금지현 | Q18: 시트 | R18: 상품 | S18: 조재민
A19: 삼성물산 | B19: 권선6구역 래미안 매교역 팰루시드(막차 납품) | C19: 케이씨씨글라스 | D19: '2026.04 | F19: CC660NLT | H19: 426 | I19: 157944 | J19: 27 | K19: =IFERROR(J19*H19,"0") -> 11502 | L19: =IFERROR(K19/1000,"0") -> 11.502 | M19: =I19*H19 -> 67284144 | P19: 금지현 | Q19: 일체형양변기 | R19: 위생도기 | S19: 조재민
A20: 삼성물산 | B20: 권선6구역 래미안 매교역 팰루시드(막차 납품) | C20: 케이씨씨글라스 | D20: '2026.04 | F20: TSC416D | H20: 344 | I20: 11649 | J20: 0 | K20: =IFERROR(J20*H20,"0") -> 0 | L20: =IFERROR(K20/1000,"0") -> 0 | M20: =I20*H20 -> 4007256 | P20: 금지현 | Q20: 시트 | R20: 상품 | S20: 조재민
... A29: 신원종합개발 | B29: 안양동 오피스텔 신축공사 현장_비주거 | C29: 다원리미티드 | D29: '2026.04 | F29: DL-B6310 | H29: 54 | I29: 81739 | J29: 0 | K29: =IFERROR(J29*H29,"0") -> 0 | L29: =IFERROR(K29/1000,"0") -> 0 | M29: =I29*H29 -> 4413906 | P29: 금지현 | Q29: 레인샤워 | R29: 수전 | S29: 윤영재
A30: 다원앤컴퍼니 | B30: 강원도 정선 하이원리조트 그랜드호텔, 마운틴콘도 리모델링 | C30: 시내울산업 | D30: '2027.01 | F30: CC830 | H30: 443 | I30: 242005 | J30: 34.2 | K30: =IFERROR(J30*H30,"0") -> 15150.6 | L30: =IFERROR(K30/1000,"0") -> 15.1506 | M30: =I30*H30 -> 107208215 | O30: 설치비 제외 | P30: 금지현 | Q30: 일체형양변기 | R30: 위생도기 | S30: 변상익
A31: 다원앤컴퍼니 | B31: 강원도 정선 하이원리조트 그랜드호텔, 마운틴콘도 리모델링 | C31: 시내울산업 | D31: '2027.01 | F31: DL-P4010 | H31: 1085 | I31: 2281 | J31: 0 | K31: =IFERROR(J31*H31,"0") -> 0 | L31: =IFERROR(K31/1000,"0") -> 0 | M31: =I31*H31 -> 2474885 | O31: 설치비 제외 | P31: 금지현 | Q31: 기타수전 | R31: 수전 | S31: 변상익
A32: 다원앤컴퍼니 | B32: 강원도 정선 하이원리조트 그랜드호텔, 마운틴콘도 리모델링 | C32: 시내울산업 | D32: '2027.01 | F32: CC550 | H32: 48 | I32: 196675 | J32: 26.2 | K32: =IFERROR(J32*H32,"0") -> 1257.6 | L32: =IFERROR(K32/1000,"0") -> 1.2576 | M32: =I32*H32 -> 9440400 | O32: 설치비 제외 | P32: 금지현 | Q32: 일체형양변기 | R32: 위생도기 | S32: 변상익
A33: 다원앤컴퍼니 | B33: 강원도 정선 하이원리조트 그랜드호텔, 마운틴콘도 리모델링 | C33: 시내울산업 | D33: '2027.01 | F33: CC670EKT | H33: 32 | I33: 173412 | J33: 29.3 | K33: =IFERROR(J33*H33,"0") -> 937.6 | L33: =IFERROR(K33/1000,"0") -> 0.9376 | M33: =I33*H33 -> 5549184 | O33: 설치비 제외 | P33: 금지현 | Q33: 일체형양변기 | R33: 위생도기 | S33: 변상익
A34: 다원앤컴퍼니 | B34: 강원도 정선 하이원리조트 그랜드호텔, 마운틴콘도 리모델링 | C34: 시내울산업 | D34: '2027.01 | F34: CC260 | H34: 562 | I34: 224490 | J34: 42.3 | K34: =IFERROR(J34*H34,"0") -> 23772.6 | L34: =IFERROR(K34/1000,"0") -> 23.7726 | M34: =I34*H34 -> 126163380 | P34: 금지현 | Q34: 원피스 | R34: 위생도기 | S34: 변상익
A35: 다원앤컴퍼니 | B35: 강원도 정선 하이원리조트 그랜드호텔, 마운틴콘도 리모델링 | C35: 시내울산업 | D35: '2027.01 | F35: DL-P4010 | H35: 562 | I35: 3233 | J35: 0 | K35: =IFERROR(J35*H35,"0") -> 0 | L35: =IFERROR(K35/1000,"0") -> 0 | M35: =I35*H35 -> 1816946 | P35: 금지현 | Q35: 기타수전 | R35: 수전 | S35: 변상익
A36: 다원앤컴퍼니 | B36: 강원도 정선 하이원리조트 그랜드호텔, 마운틴콘도 리모델링 | C36: 시내울산업 | D36: '2027.01 | F36: CL310 | H36: 446 | I36: 55940 | J36: 16 | K36: =IFERROR(J36*H36,"0") -> 7136 | L36: =IFERROR(K36/1000,"0") -> 7.136 | M36: =I36*H36 -> 24949240 | O36: 타월바 15,000원 별도 | P36: 금지현 | Q36: 평면붙임세면기 | R36: OEM | S36: 변상익
A37: 다원앤컴퍼니 | B37: 강원도 정선 하이원리조트 그랜드호텔, 마운틴콘도 리모델링 | C37: 시내울산업 | D37: '2027.01 | F37: CL340N | H37: 60 | I37: 86400 | J37: 19 | K37: =IFERROR(J37*H37,"0") -> 1140 | L37: =IFERROR(K37/1000,"0") -> 1.14 | M37: =I37*H37 -> 5184000 | O37: CL-340N 적용(비누대 없는 사양) | P37: 금지현 | Q37: 세미탑볼 | R37: 위생도기 | S37: 변상익
A38: 다원앤컴퍼니 | B38: 강원도 정선 하이원리조트 그랜드호텔, 마운틴콘도 리모델링 | C38: 시내울산업 | D38: '2027.01 | F38: CL610F | H38: 75 | I38: 87379 | J38: 10.5 | K38: =IFERROR(J38*H38,"0") -> 787.5 | L38: =IFERROR(K38/1000,"0") -> 0.7875 | M38: =I38*H38 -> 6553425 | P38: 금지현 | Q38: 언더카운터 | R38: 위생도기 | S38: 변상익
A39: 다원앤컴퍼니 | B39: 강원도 정선 하이원리조트 그랜드호텔, 마운틴콘도 리모델링 | C39: 시내울산업 | D39: '2027.01 | F39: CC116 | H39: 7 | I39: 121858 | J39: 40 | K39: =IFERROR(J39*H39,"0") -> 280 | L39: =IFERROR(K39/1000,"0") -> 0.28 | M39: =I39*H39 -> 853006 | P39: 금지현 | Q39: F/V양변기 | R39: OEM | S39: 변상익
A40: 다원앤컴퍼니 | B40: 강원도 정선 하이원리조트 그랜드호텔, 마운틴콘도 리모델링 | C40: 시내울산업 | D40: '2027.01 | F40: CU600P | H40: 15 | I40: 231954 | J40: 39 | K40: =IFERROR(J40*H40,"0") -> 585 | L40: =IFERROR(K40/1000,"0") -> 0.585 | M40: =I40*H40 -> 3479310 | P40: 금지현 | Q40: 소변기 | R40: 위생도기 | S40: 변상익
A41: 다원앤컴퍼니 | B41: 강원도 정선 하이원리조트 그랜드호텔, 마운틴콘도 리모델링 | C41: 시내울산업 | D41: '2027.01 | F41: DL-L8010 | H41: 7 | I41: 105294 | J41: 0 | K41: =IFERROR(J41*H41,"0") -> 0 | L41: =IFERROR(K41/1000,"0") -> 0 | M41: =I41*H41 -> 737058 | P41: 금지현 | Q41: 세면수전 | R41: 수전 | S41: 변상익
A42: 다원앤컴퍼니 | B42: 강원도 정선 하이원리조트 그랜드호텔, 마운틴콘도 리모델링 | C42: 시내울산업 | D42: '2027.01 | F42: DL-P4050 | H42: 32 | I42: 99000 | J42: 0 | K42: =IFERROR(J42*H42,"0") -> 0 | L42: =IFERROR(K42/1000,"0") -> 0 | M42: =I42*H42 -> 3168000 | P42: 금지현 | Q42: 기타수전 | R42: 수전 | S42: 변상익
A43: 다원앤컴퍼니 | B43: 강원도 정선 하이원리조트 그랜드호텔, 마운틴콘도 리모델링 | C43: 시내울산업 | D43: '2027.01 | F43: DL-P4052 | H43: 32 | I43: 77400 | J43: 0 | K43: =IFERROR(J43*H43,"0") -> 0 | L43: =IFERROR(K43/1000,"0") -> 0 | M43: =I43*H43 -> 2476800 | P43: 금지현 | Q43: 기타수전 | R43: 수전 | S43: 변상익
A44: 서한건설 | B44: 평택 고덕국제신도시 서한 이다음 그레이튼 | C44: 미정 | D44: '2027.12 | F44: DL-K6219 | H44: 1138 | I44: 87300 | J44: 0 | K44: =IFERROR(J44*H44,"0") -> 0 | L44: =IFERROR(K44/1000,"0") -> 0 | M44: =I44*H44 -> 99347400 | P44: 금지현 | Q44: 싱크수전 | R44: 수전 | S44: 박기진
A45: 서한건설 | B45: 평택 고덕국제신도시 서한 이다음 그레이튼 | C45: 미정 | D45: '2027.12 | F45: DL-G4241C | H45: 1138 | I45: 11218 | J45: 0 | K45: =IFERROR(J45*H45,"0") -> 0 | L45: =IFERROR(K45/1000,"0") -> 0 | M45: =I45*H45 -> 12766084 | P45: 금지현 | Q45: 기타수전 | R45: 수전 | S45: 박기진
A46: 서한건설 | B46: 평택 고덕국제신도시 서한 이다음 그레이튼 | C46: 미정 | D46: '2027.12 | F46: DL-P4201 | H46: 1138 | I46: 641 | J46: 0 | K46: =IFERROR(J46*H46,"0") -> 0 | L46: =IFERROR(K46/1000,"0") -> 0 | M46: =I46*H46 -> 729458 | P46: 금지현 | Q46: 기타수전 | R46: 수전 | S46: 박기진
A47: 서한건설 | B47: 평택 고덕국제신도시 서한 이다음 그레이튼 | C47: 미정 | D47: '2027.12 | F47: DL-P4202 | H47: 1138 | I47: 4487 | J47: 0 | K47: =IFERROR(J47*H47,"0") -> 0 | L47: =IFERROR(K47/1000,"0") -> 0 | M47: =I47*H47 -> 5106206 | P47: 금지현 | Q47: 기타수전 | R47: 수전 | S47: 박기진
A48: 서한건설 | B48: 평택 고덕국제신도시 서한 이다음 그레이튼 | C48: 미정 | D48: '2027.12 | F48: DL-S4195 | H48: 1138 | I48: 6154 | J48: 0 | K48: =IFERROR(J48*H48,"0") -> 0 | L48: =IFERROR(K48/1000,"0") -> 0 | M48: =I48*H48 -> 7003252 | P48: 금지현 | Q48: 기타수전 | R48: 수전 | S48: 박기진
...

Sheet ※비데 납품계획
A1: 2026년 01월 ~ 2026년 12월 리테일부문 비데 납품계획
C2: 구분 | E2: '2026.01 | F2: '2026.02 | G2: '2026.03 | H2: '2026.04 | I2: '2026.05 | J2: '2026.06 | K2: '2026.07 | L2: '2026.08 | M2: '2026.09 | N2: '2026.10 | O2: '2026.11 | P2: '2026.12 | Q2: 합계
C3: 분리형비데 | D3: 수량 | E3: =SUMIFS($H$11:$H$131,$D$11:$D$131,E2,$Q$11:$Q$131,$C$3) -> 0 | F3: =SUMIFS($H$11:$H$131,$D$11:$D$131,F2,$Q$11:$Q$131,$C$3) -> 0 | G3: =SUMIFS($H$11:$H$131,$D$11:$D$131,G2,$Q$11:$Q$131,$C$3) -> 0 | H3: =SUMIFS($H$11:$H$131,$D$11:$D$131,H2,$Q$11:$Q$131,$C$3) -> 2267 | I3: =SUMIFS($H$11:$H$131,$D$11:$D$131,I2,$Q$11:$Q$131,$C$3) -> 1856 | J3: =SUMIFS($H$11:$H$131,$D$11:$D$131,J2,$Q$11:$Q$131,$C$3) -> 1733 | K3: =SUMIFS($H$11:$H$131,$D$11:$D$131,K2,$Q$11:$Q$131,$C$3) -> 99 | L3: =SUMIFS($H$11:$H$131,$D$11:$D$131,L2,$Q$11:$Q$131,$C$3) -> 599 | ... P3: =SUMIFS($H$11:$H$131,$D$11:$D$131,P2,$Q$11:$Q$131,$C$3) -> 726 | Q3: =SUM(E3:P3) -> 8229 | R3: 수량
C4: 분리형비데 | D4: 금액 | E4: =SUMIFS($M$11:$M$131,$D$11:$D$131,E2,$Q$11:$Q$131,$C$4) -> 0 | F4: =SUMIFS($M$11:$M$131,$D$11:$D$131,F2,$Q$11:$Q$131,$C$4) -> 0 | G4: =SUMIFS($M$11:$M$131,$D$11:$D$131,G2,$Q$11:$Q$131,$C$4) -> 0 | H4: =SUMIFS($M$11:$M$131,$D$11:$D$131,H2,$Q$11:$Q$131,$C$4) -> 278182800 | I4: =SUMIFS($M$11:$M$131,$D$11:$D$131,I2,$Q$11:$Q$131,$C$4) -> 212485000 | J4: =SUMIFS($M$11:$M$131,$D$11:$D$131,J2,$Q$11:$Q$131,$C$4) -> 206141000 | K4: =SUMIFS($M$11:$M$131,$D$11:$D$131,K2,$Q$11:$Q$131,$C$4) -> 11385000 | L4: =SUMIFS($M$11:$M$131,$D$11:$D$131,L2,$Q$11:$Q$131,$C$4) -> 71280200 | ... P4: =SUMIFS($M$11:$M$131,$D$11:$D$131,P2,$Q$11:$Q$131,$C$4) -> 101640000 | Q4: =SUM(E4:P4) -> 992147000 | R4: 금액
C5: 일체형비데 | D5: 수량 | E5: =SUMIFS($H$11:$H$131,$D$11:$D$131,E2,$Q$11:$Q$131,$C$6) -> 0 | F5: =SUMIFS($H$11:$H$131,$D$11:$D$131,F2,$Q$11:$Q$131,$C$6) -> 0 | G5: =SUMIFS($H$11:$H$131,$D$11:$D$131,G2,$Q$11:$Q$131,$C$6) -> 0 | H5: =SUMIFS($H$11:$H$131,$D$11:$D$131,H2,$Q$11:$Q$131,$C$6) -> 3410 | I5: =SUMIFS($H$11:$H$131,$D$11:$D$131,I2,$Q$11:$Q$131,$C$6) -> 1212 | J5: =SUMIFS($H$11:$H$131,$D$11:$D$131,J2,$Q$11:$Q$131,$C$6) -> 9652 | K5: =SUMIFS($H$11:$H$131,$D$11:$D$131,K2,$Q$11:$Q$131,$C$6) -> 310 | L5: =SUMIFS($H$11:$H$131,$D$11:$D$131,L2,$Q$11:$Q$131,$C$6) -> 1304 | ... P5: =SUMIFS($H$11:$H$131,$D$11:$D$131,P2,$Q$11:$Q$131,$C$6) -> 2532 | Q5: =SUM(E5:P5) -> 20672 | R5: 수량
C6: 일체형비데 | D6: 금액 | E6: =SUMIFS($M$11:$M$131,$D$11:$D$131,E2,$Q$11:$Q$131,$C$6) -> 0 | F6: =SUMIFS($M$11:$M$131,$D$11:$D$131,F2,$Q$11:$Q$131,$C$6) -> 0 | G6: =SUMIFS($M$11:$M$131,$D$11:$D$131,G2,$Q$11:$Q$131,$C$6) -> 0 | H6: =SUMIFS($M$11:$M$131,$D$11:$D$131,H2,$Q$11:$Q$131,$C$6) -> 8.897353e+08 | I6: =SUMIFS($M$11:$M$131,$D$11:$D$131,I2,$Q$11:$Q$131,$C$6) -> 2.5892329e+08 | J6: =SUMIFS($M$11:$M$131,$D$11:$D$131,J2,$Q$11:$Q$131,$C$6) -> 2977619133 | K6: =SUMIFS($M$11:$M$131,$D$11:$D$131,K2,$Q$11:$Q$131,$C$6) -> 55863750 | L6: =SUMIFS($M$11:$M$131,$D$11:$D$131,L2,$Q$11:$Q$131,$C$6) -> 180719398 | ... P6: =SUMIFS($M$11:$M$131,$D$11:$D$131,P2,$Q$11:$Q$131,$C$6) -> 521490714 | Q6: =SUM(E6:P6) -> 5.343784e+09 | R6: 금액
C7: 합계 | D7: 수량 | E7: =E3+E5 -> 0 | F7: =F3+F5 -> 0 | G7: =G3+G5 -> 0 | H7: =H3+H5 -> 5677 | I7: =I3+I5 -> 3068 | J7: =J3+J5 -> 11385 | K7: =K3+K5 -> 409 | L7: =L3+L5 -> 1903 | ... P7: =P3+P5 -> 3258 | Q7: =SUM(E7:P7) -> 28901 | R7: 수량
C8: 합계 | D8: 금액 | E8: =E6+E4 -> 0 | F8: =F6+F4 -> 0 | G8: =G6+G4 -> 0 | H8: =H6+H4 -> 1.1679181e+09 | I8: =I6+I4 -> 4.7140829e+08 | J8: =J6+J4 -> 3183760133 | K8: =K6+K4 -> 67248750 | L8: =L6+L4 -> 251999598 | ... P8: =P6+P4 -> 623130714 | Q8: =SUM(E8:P8) -> 6.335931e+09 | R8: 금액
A11: 건설회사 | B11: 현장명 | C11: 대리점 | D11: 납품예정 | E11: 입주예정 | F11: 품목 | G11: 색상 | H11: 수량 | I11: 대리점가 | J11: 중량(KG) | K11: 총무게(KG) | L11: 총무게(TON) | M11: 금액 | N11: 특수사양 | O11: 비고 | P11: 담당자 | Q11: 품목 | R11: 구분 | S11: SPEC담당
A12: 아주건설 | B12: 제주 아주 더 하이클래스 현장 | C12: 케이에스비시스템 | D12: '2026.04 | F12: DST-680N | H12: 20 | I12: 179695 | J12: 9.4 | K12: 188 | L12: 0.188 | M12: 3593900 | P12: 권순호 | Q12: 일체형비데 | R12: 비데 | S12: 윤영재
A13: 태왕이앤씨 | B13: 대구 태왕아너스 프리미어(성창 재건축)(1차 납품) | C13: 홈센타홀딩스 | D13: '2026.05 | F13: DST-1300LS | H13: 200 | I13: 128000 | K13: 0 | L13: 0 | M13: 25600000 | N13: 일반 도소매 사양 | P13: 조동욱 | Q13: 분리형비데 | R13: 비데
A14: 설해원 | B14: 설해수림 | C14: 시내울산업 | D14: '2026.04 | F14: DST-680NR | H14: 32 | I14: 191836 | K14: 0 | L14: 0 | M14: 6138752 | N14: R-BAR 리모콘 적용 | P14: 금지현 | Q14: 일체형비데 | R14: 비데
A15: 코오롱건설 | B15: 권선6구역 래미안 매교역 팰루시드 | C15: 홈센타홀딩스 | D15: '2026.06 | F15: DST-660N | H15: 815 | I15: 190983 | K15: 0 | L15: 0 | M15: 155651145 | N15: 일반 도소매 사양 | P15: 조동욱 | Q15: 일체형비데 | R15: 비데
A16: 현대건설 | B16: 인천 청라 드림타운 | C16: 직납 | D16: '2026.04 | F16: DST-550F | H16: 404 | I16: 340000 | K16: 0 | L16: 0 | M16: 137360000 | N16: FULEN | O16: 급수호스 및 전원코드 길이 특수사양 | P16: 김광제 | Q16: 일체형비데 | R16: 비데
A17: 현대산업개발 | B17: 춘천 레이크시티 아이파크 | C17: 케이디시스템 | D17: '2026.05 | F17: DST-8000F | H17: 34 | I17: 637164 | K17: 0 | L17: 0 | M17: 21663576 | N17: FULEN | P17: 최윤한 | Q17: 일체형비데 | R17: 비데
A18: DL건설 | B18: e편한세상 제물포역 파크메종 | C18: 직납 | D18: '2026.06 | F18: DST-660N | H18: 186 | I18: 183825 | K18: 0 | L18: 0 | M18: 34191450 | N18: 일반 도소매 사양 | P18: 박준혁 | Q18: 일체형비데 | R18: 비데
A19: 한국기술서비스 | B19: 서울 지하철통합관제센터 | C19: 케이디시스템 | D19: '2026.08 | F19: DST-1700 | H19: 22 | I19: 120600 | K19: 0 | L19: 0 | M19: 2653200 | N19: 일반 도소매 사양 | P19: 최윤한 | Q19: 분리형비데 | R19: 비데
A20: 중흥건설 | B20: 광주 송정공원 중흥S-클래스 | C20: 신우세라믹 | D20: '2026.06 | F20: DST-670 | H20: 298 | I20: 178000 | K20: 0 | L20: 0 | M20: 53044000 | N20: 일반 도소매 사양 | P20: 김혜림 | Q20: 일체형비데 | R20: 비데
A21: 호반건설 | B21: 오산 세교2지구 A13블럭 호반써밋 라프리미어 | C21: 기흔인터내셔널 | D21: '2026.05 | F21: DST-660N | H21: 388 | I21: 167983 | K21: 0 | L21: 0 | M21: 65177404 | N21: 일반 도소매 사양 | P21: 백세현 | Q21: 일체형비데 | R21: 비데
A22: GS건설 | B22: 안양 자이 더포레스트(화창지구)현장 | C22: 레코드 | D22: '2026.04 | F22: DST-680NR | H22: 492 | I22: 174886 | K22: 0 | L22: 0 | M22: 86043912 | N22: R-BAR 리모콘 적용 | P22: 백성렬 | Q22: 일체형비데 | R22: 비데
A23: (주)한화 | B23: 포레나 안산 고잔2차 | C23: 하나도기 | D23: '2026.06 | F23: DST-1300RLS | H23: 169 | I23: 137000 | K23: 0 | L23: 0 | M23: 23153000 | N23: 일반 도소매 사양 | P23: 이승현2 | Q23: 분리형비데 | R23: 비데
A24: 현대엔지니어링 | B24: 힐스테이트 속초 | C24: 직납 | D24: '2026.05 | F24: DST-670 | H24: 30 | I24: 204333 | K24: 0 | L24: 0 | M24: 6129990 | N24: 일반 도소매 사양 | P24: 김광제 | Q24: 일체형비데 | R24: 비데
A25: DL건설 | B25: e편한세상 평촌 어반밸리 | C25: 직납 | D25: '2026.05 | F25: DST-1300LS | H25: 313 | I25: 117000 | K25: 0 | L25: 0 | M25: 36621000 | N25: 일반 도소매 사양 | O25: 옵션수량 변동가능성 有 | P25: 박준혁 | Q25: 분리형비데 | R25: 비데
A26: 롯데건설 | B26: 인천 검단 롯데캐슬 넥스티엘 | C26: 티엔씨시스템 | D26: '2026.04 | F26: DST-8000F | H26: 64 | I26: 602251 | K26: 0 | L26: 0 | M26: 38544064 | N26: FULEN | P26: 백세현 | Q26: 일체형비데 | R26: 비데
A27: DL건설 | B27: e편한세상 대전역 센텀비스타 | C27: 직납 | D27: '2026.04 | F27: DST-1300LS | H27: 348 | I27: 117000 | K27: 0 | L27: 0 | M27: 40716000 | N27: 일반 도소매 사양 | O27: 옵션수량 변동가능성 有 | P27: 박준혁 | Q27: 분리형비데 | R27: 비데
A28: DL건설 | B28: e편한세상 대전역 센텀비스타 | C28: 직납 | D28: '2026.04 | F28: DST-660N | H28: 154 | I28: 183825 | K28: 0 | L28: 0 | M28: 28309050 | N28: 일반 도소매 사양 | O28: 옵션수량 변동가능성 有 | P28: 박준혁 | Q28: 일체형비데 | R28: 비데
A29: DL이앤씨 | B29: 부산 e편한세상 금정 메종카운티 | C29: 직납 | D29: '2026.05 | F29: DST-1300LS | H29: 362 | I29: 117000 | K29: 0 | L29: 0 | M29: 42354000 | N29: 일반 도소매 사양 | P29: 박준혁 | Q29: 분리형비데 | R29: 비데
A30: DL이앤씨 | B30: 경기 e편한세상 시흥 더블스퀘어 현장(재건축, APT) | C30: 직납 | D30: '2026.04 | F30: DST-1300LS | H30: 899 | I30: 117000 | K30: 0 | L30: 0 | M30: 105183000 | N30: 일반 도소매 사양 | P30: 김주오 | Q30: 분리형비데 | R30: 비데
A31: DL이앤씨 | B31: e편한세상 시흥 더블스퀘어_추가 | C31: 직납 | D31: '2026.04 | F31: DST-660N | H31: 232 | I31: 176008 | K31: 0 | L31: 0 | M31: 40833856 | N31: 일반 도소매 사양 | P31: 김주오 | Q31: 일체형비데 | R31: 비데
A32: GS건설 | B32: 의왕 내손 라 구역(1차 납품) | C32: 세광도기 | D32: '2026.04 | F32: DST-8000F | H32: 1020 | I32: 350000 | K32: 0 | L32: 0 | M32: 357000000 | N32: FULEN | P32: 김정완 | Q32: 일체형비데 | R32: 비데
A33: GS건설 | B33: 의왕 내손 라 구역(막차 납품) | C33: 세광도기 | D33: '2026.05 | F33: DST-8000F | H33: 295 | I33: 350000 | K33: 0 | L33: 0 | M33: 103250000 | N33: FULEN | P33: 김정완 | Q33: 일체형비데 | R33: 비데
A34: DL건설 | B34: 인천 e편한세상 검단 에코비스타 | C34: 직납 | D34: '2026.05 | F34: DST-660N | H34: 348 | I34: 176008 | K34: 0 | L34: 0 | M34: 61250784 | N34: 일반 도소매 사양 | O34: 옵션수량 변동가능성 有 | P34: 박준혁 | Q34: 일체형비데 | R34: 비데
A35: 중흥건설 | B35: 부산 에코델타시티 16블록 중흥S-클래스 | C35: 태욱 | D35: '2026.08 | F35: DST-670 | H35: 694 | I35: 178000 | K35: 0 | L35: 0 | M35: 123532000 | N35: 일반 도소매 사양 | P35: 김혜림 | Q35: 일체형비데 | R35: 비데
A36: DL이앤씨 | B36: 인천 e편한세상 검단 웰카운티 | C36: 직납 | D36: '2026.06 | F36: DST-1300LS | H36: 1094 | I36: 117000 | K36: 0 | L36: 0 | M36: 127998000 | N36: 일반 도소매 사양 | P36: 박준혁 | Q36: 분리형비데 | R36: 비데
A37: DL이앤씨 | B37: 인천 e편한세상 검단 웰카운티 | C37: 직납 | D37: '2026.06 | F37: DST-660N | H37: 330 | I37: 183825 | K37: 0 | L37: 0 | M37: 60662250 | N37: 일반 도소매 사양 | P37: 박준혁 | Q37: 일체형비데 | R37: 비데
A38: SK건설 | B38: 권선6구역 래미안 매교역 팰루시드 | C38: 케이에스비시스템 | D38: '2026.04 | F38: DST-660N | H38: 973 | I38: 190983 | K38: 0 | L38: 0 | M38: 185826459 | N38: 일반 도소매 사양 | P38: 권순호 | Q38: 일체형비데 | R38: 비데
A39: 현대건설 | B39: 방배5구역 (디에이치방배) 재개발 조합 | C39: 직납 | D39: '2026.06 | F39: DST-550F | H39: 3020 | I39: 371583 | K39: 0 | L39: 0 | M39: 1122180660 | N39: FULEN | P39: 김광제 | Q39: 일체형비데 | R39: 비데
A40: 현대건설 | B40: 방배5구역 (디에이치방배) 재개발 조합 | C40: 직납 | D40: '2026.06 | F40: DST-8101F | H40: 3078 | I40: 371583 | K40: 0 | L40: 0 | M40: 1143732474 | N40: FULEN | P40: 김광제 | Q40: 일체형비데 | R40: 비데
A41: 현대건설 | B41: 방배5구역 (디에이치방배) 재건축 조합 | C41: 직납 | D41: '2026.06 | F41: DST-8000F | H41: 45 | I41: 789810 | K41: 0 | L41: 0 | M41: 35541450 | N41: FULEN | P41: 김광제 | Q41: 일체형비데 | R41: 비데
A42: 신안건설산업 | B42: 이천백사지구 지역주택조합(신안 실크밸리 추가) | C42: 하나도기 | D42: '2026.05 | F42: DST-1700 | H42: 981 | I42: 110000 | K42: 0 | L42: 0 | M42: 107910000 | N42: 일반 도소매 사양 | P42: 이승현2 | Q42: 분리형비데 | R42: 비데
...

Sheet ※일정변경내역
E1: 3월 → X월 | F1: =SUM(F3:F7) -> 2480014746
A2: □ V1_26.03 리테일부문 현장별 납품 계획_20260305 대비 변경, 수정 내역(일정, 수량) | D2: '2026.03 | E2: 구분 | F2: 금액
E3: 위생도기 | F3: =SUMIFS($O$8:$O$476,$T$8:$T$476,E3,$D$8:$D$476,$D$2) -> 1678558095
E4: OEM | F4: =SUMIFS($O$8:$O$476,$T$8:$T$476,E4,$D$8:$D$476,$D$2) -> 178708720
E5: 상품 | F5: =SUMIFS($O$8:$O$476,$T$8:$T$476,E5,$D$8:$D$476,$D$2) -> 104511418
E6: 수전 | F6: =SUMIFS($O$8:$O$476,$T$8:$T$476,E6,$D$8:$D$476,$D$2) -> 470972937
E7: 비데 | F7: =SUMIFS($O$8:$O$476,$T$8:$T$476,E7,$D$8:$D$476,$D$2) -> 47263576 | M7: 2362000000 | N7: =SUBTOTAL(9,N9:N7607) -> 14860723403 | O7: =SUBTOTAL(9,O9:O7607) -> 11978027713 | U7: (단위 : EA,원)
A8: 건설회사 | B8: 현장명 | C8: 대리점 | D8: 기존일정 | E8: 변경일정 | F8: 품목 | G8: 색상 | H8: 기존수량 | I8: 이월수량 | J8: 대리점가 | K8: 중량(KG) | L8: 총무게(KG) | M8: 총무게(TON) | N8: 기존금액 | O8: 이월금액 | P8: 특수사양 | Q8: 비고 | R8: 담당자 | S8: 품목 | T8: 구분 | U8: SPEC담당
A9: (주)대우건설 | B9: 대우건설 영종A9 후분양 현장(자체사업,APT) | C9: 세광도기 | D9: '2026.03 | E9: '2026.04 | F9: CC740 | H9: 1694 | I9: 1694 | J9: 158600 | K9: 36 | L9: =IFERROR(K9*H9,"0") -> 60984 | M9: =IFERROR(L9/1000,"0") -> 60.984 | N9: =J9*H9 -> 268668400 | O9: =I9*J9 -> 268668400 | Q9: 부속(대소구분레버),신형정심후렌지(202VN)1EA,앵글밸브1EA포함/시트제외 | R9: 김정완 | S9: 치마형투피스 | T9: 위생도기 | U9: 김주석
A10: (주)대우건설 | B10: 대우건설 영종A9 후분양 현장(자체사업,APT) | C10: 세광도기 | D10: '2026.03 | E10: '2026.05 | F10: CL336P | H10: 1694 | I10: 1694 | J10: 12381 | K10: 0 | L10: =IFERROR(K10*H10,"0") -> 0 | M10: =IFERROR(L10/1000,"0") -> 0 | N10: =J10*H10 -> 20973414 | O10: =I10*J10 -> 20973414 | R10: 김정완 | S10: 페데스탈 | T10: 상품 | U10: 김주석
A11: (주)대우건설 | B11: 대우건설 영종A9 후분양 현장(자체사업,APT) | C11: 세광도기 | D11: '2026.03 | E11: '2026.04 | F11: CLR336W | H11: 1694 | I11: 1694 | J11: 55834 | K11: 16 | L11: =IFERROR(K11*H11,"0") -> 27104 | M11: =IFERROR(L11/1000,"0") -> 27.104 | N11: =J11*H11 -> 94582796 | O11: =I11*J11 -> 94582796 | Q11: ABS반다리적용,앙카(세면기,반다리)포함/별도폽업타공 | R11: 김정완 | S11: 벽붙이세면기 | T11: 위생도기 | U11: 김주석
A12: (주)대우건설 | B12: 대우건설 영종A9 후분양 현장(자체사업,APT) | C12: 세광도기 | D12: '2026.03 | E12: '2026.05 | F12: TSC416D | H12: 847 | I12: 847 | J12: 10065 | K12: 0 | L12: =IFERROR(K12*H12,"0") -> 0 | M12: =IFERROR(L12/1000,"0") -> 0 | N12: =J12*H12 -> 8525055 | O12: =I12*J12 -> 8525055 | R12: 김정완 | S12: 시트 | T12: 상품 | U12: 김주석
A13: 현대건설 | B13: 힐스테이트 이천역 | C13: 직납 | D13: '2026.03 | E13: '2026.04 | F13: CC740 | H13: 2090 | I13: 1090 | J13: 122068 | K13: 36.4 | L13: =IFERROR(K13*H13,"0") -> 76076 | M13: =IFERROR(L13/1000,"0") -> 76.076 | N13: =J13*H13 -> 255122120 | O13: =I13*J13 -> 133054120 | R13: 김광제 | S13: 치마형투피스 | T13: 위생도기 | U13: 박성진
A14: 대우건설 | B14: 논산푸르지오 더퍼스트 | C14: 엔와이산업 | D14: '2026.03 | E14: '2026.04 | F14: CC740 | H14: 866 | I14: 566 | J14: 152100 | K14: 36.4 | L14: =IFERROR(K14*H14,"0") -> 31522.4 | M14: =IFERROR(L14/1000,"0") -> 31.5224 | N14: =J14*H14 -> 131718600 | O14: =I14*J14 -> 86088600 | R14: 조동욱 | S14: 치마형투피스 | T14: 위생도기 | U14: 변상익
A15: 대우건설 | B15: 송내역 푸르지오 센트비엔 | C15: 세광도기 | D15: '2026.03 | E15: '2026.04 | F15: CC740 | H15: 952 | I15: 552 | J15: 146541 | K15: 36.4 | L15: =IFERROR(K15*H15,"0") -> 34652.8 | M15: =IFERROR(L15/1000,"0") -> 34.6528 | N15: =J15*H15 -> 139507032 | O15: =I15*J15 -> 80890632 | R15: 김정완 | S15: 치마형투피스 | T15: 위생도기 | U15: 박기진
A16: 호반건설 | B16: 천안 일봉공원 호반써밋 센트럴파크 2블록(막차 납품) | C16: 기흔인터내셔널 | D16: '2026.03 | E16: '2026.04 | F16: CC740 | H16: 489 | I16: 489 | J16: 156000 | K16: 36.4 | L16: =IFERROR(K16*H16,"0") -> 17799.6 | M16: =IFERROR(L16/1000,"0") -> 17.7996 | N16: =J16*H16 -> 76284000 | O16: =I16*J16 -> 76284000 | R16: 백세현 | S16: 치마형투피스 | T16: 위생도기 | U16: 최윤한
A17: (주)대우건설 | B17: 대우건설 영종A9 후분양 현장(자체사업,APT) | C17: 세광도기 | D17: '2026.04 | E17: '2026.05 | F17: CC740 | H17: 1694 | I17: 594 | J17: 158600 | K17: 36 | L17: =IFERROR(K17*H17,"0") -> 60984 | M17: =IFERROR(L17/1000,"0") -> 60.984 | N17: =J17*H17 -> 268668400 | O17: =I17*J17 -> 94208400 | Q17: 부속(대소구분레버),신형정심후렌지(202VN)1EA,앵글밸브1EA포함/시트제외 | R17: 김정완 | S17: 치마형투피스 | T17: 위생도기 | U17: 김주석
A18: 호반건설 | B18: 인천 검단신도시(AB13블럭) 호반써밋3차 | C18: 기흔인터내셔널 | D18: '2026.04 | E18: '2026.05 | F18: CC740 | H18: 469 | I18: 469 | J18: 183111 | K18: 36.4 | L18: =IFERROR(K18*H18,"0") -> 17071.6 | M18: =IFERROR(L18/1000,"0") -> 17.0716 | N18: =J18*H18 -> 85879059 | O18: =I18*J18 -> 85879059 | R18: 백세현 | S18: 치마형투피스 | T18: 위생도기 | U18: 조재민
A19: 현대건설 | B19: 힐스테이트 구미 더 퍼스트(1차 납품) | C19: 직납 | D19: '2026.05 | E19: '2026.06 | F19: CC740 | H19: 585 | I19: 585 | J19: 176321 | K19: 36.4 | L19: =IFERROR(K19*H19,"0") -> 21294 | M19: =IFERROR(L19/1000,"0") -> 21.294 | N19: =J19*H19 -> 103147785 | O19: =I19*J19 -> 103147785 | R19: 김광제 | S19: 치마형투피스 | T19: 위생도기 | U19: 박성진
A20: 현대건설 | B20: 메디알레 은평대조1구역 | C20: 직납 | D20: '2026.05 | E20: '2026.06 | F20: CC740 | H20: 869 | I20: 269 | J20: 176321 | K20: 36.4 | L20: =IFERROR(K20*H20,"0") -> 31631.6 | M20: =IFERROR(L20/1000,"0") -> 31.6316 | N20: =J20*H20 -> 153222949 | O20: =I20*J20 -> 47430349 | Q20: 시트제외 | R20: 김광제 | S20: 치마형투피스 | T20: 위생도기 | U20: 박성진
A21: 현대건설 | B21: 힐스테이트 등촌역 | C21: 직납 | D21: '2026.05 | E21: '2026.06 | F21: CC740 | H21: 1086 | I21: 486 | J21: 176321 | K21: 36.4 | L21: =IFERROR(K21*H21,"0") -> 39530.4 | M21: =IFERROR(L21/1000,"0") -> 39.5304 | N21: =J21*H21 -> 191484606 | O21: =I21*J21 -> 85692006 | Q21: 시트제외 | R21: 김광제 | S21: 치마형투피스 | T21: 위생도기 | U21: 박성진
A22: 대우건설 | B22: 평택 푸르지오 센터파인 | C22: 세광도기 | D22: '2026.05 | E22: '2026.06 | F22: CC740 | H22: 1608 | I22: 808 | J22: 146541 | K22: 36.4 | L22: =IFERROR(K22*H22,"0") -> 58531.2 | M22: =IFERROR(L22/1000,"0") -> 58.5312 | N22: =J22*H22 -> 235637928 | O22: =I22*J22 -> 118405128 | R22: 김정완 | S22: 치마형투피스 | T22: 위생도기 | U22: 박기진
A23: 대우건설 | B23: 관저 푸르지오 센트럴파크 | C23: 세광도기 | D23: '2026.05 | E23: '2026.06 | F23: CC740 | H23: 1246 | I23: 646 | J23: 146541 | K23: 36.4 | L23: =IFERROR(K23*H23,"0") -> 45354.4 | M23: =IFERROR(L23/1000,"0") -> 45.3544 | N23: =J23*H23 -> 182590086 | O23: =I23*J23 -> 94665486 | R23: 김정완 | S23: 치마형투피스 | T23: 위생도기 | U23: 박기진
A24: 현대건설 | B24: 메디알레_은평대조1구역_추가분 | C24: 직납 | D24: '2026.05 | E24: '2026.06 | F24: CC740 | H24: 330 | I24: 330 | J24: 176321 | K24: 36 | L24: =IFERROR(K24*H24,"0") -> 11880 | M24: =IFERROR(L24/1000,"0") -> 11.88 | N24: =J24*H24 -> 58185930 | O24: =I24*J24 -> 58185930 | Q24: 시트제외 | R24: 김광제 | S24: 치마형투피스 | T24: 위생도기 | U24: 박성진
A25: 현대건설 | B25: 힐스테이트 마포더퍼스트 | C25: 직납 | D25: '2026.03 | E25: '2026.04 | F25: CC740 | H25: 522 | I25: 522 | J25: 176321 | K25: 36.4 | L25: =IFERROR(K25*H25,"0") -> 19000.8 | M25: =IFERROR(L25/1000,"0") -> 19.0008 | N25: =J25*H25 -> 92039562 | O25: =I25*J25 -> 92039562 | R25: 김광제 | S25: 치마형투피스 | T25: 위생도기 | U25: 박성진
A26: 대우건설 | B26: 논산푸르지오 더퍼스트(1차 납품) | C26: 엔와이산업 | D26: '2026.03 | E26: '2026.04 | F26: CC740 | H26: 300 | I26: 300 | J26: 152100 | K26: 36.4 | L26: =IFERROR(K26*H26,"0") -> 10920 | M26: =IFERROR(L26/1000,"0") -> 10.92 | N26: =J26*H26 -> 45630000 | O26: =I26*J26 -> 45630000 | R26: 조동욱 | S26: 치마형투피스 | T26: 위생도기 | U26: 변상익
A27: 극동건설 | B27: SH 마곡 지식산업센터 현장_20250916 | C27: 세일도기 | D27: '2026.03 | E27: '2026.04 | F27: CC740 | H27: 245 | I27: 245 | J27: 184737 | K27: 36 | L27: =IFERROR(K27*H27,"0") -> 8820 | M27: =IFERROR(L27/1000,"0") -> 8.82 | N27: =J27*H27 -> 45260565 | O27: =I27*J27 -> 45260565 | Q27: 시트, 양부속 포함 | R27: 금지현 | S27: 치마형투피스 | T27: 위생도기 | U27: 박성진
A28: 호반건설 | B28: 경북 위파크 안동 | C28: 기흔인터내셔널 | D28: '2026.04 | E28: '2026.05 | F28: CC740 | H28: 200 | I28: 200 | J28: 155717 | K28: 36.4 | L28: =IFERROR(K28*H28,"0") -> 7280 | M28: =IFERROR(L28/1000,"0") -> 7.28 | N28: =J28*H28 -> 31143400 | O28: =I28*J28 -> 31143400 | R28: 백세현 | S28: 투피스 | T28: 위생도기 | U28: 조재민
A29: 대우건설 | B29: 논산푸르지오 더퍼스트(막차 납품) | C29: 엔와이산업 | D29: '2026.04 | E29: '2026.05 | F29: CC740 | H29: 466 | I29: 466 | J29: 152100 | K29: 36.4 | L29: =IFERROR(K29*H29,"0") -> 16962.4 | M29: =IFERROR(L29/1000,"0") -> 16.9624 | N29: =J29*H29 -> 70878600 | O29: =I29*J29 -> 70878600 | R29: 조동욱 | S29: 치마형투피스 | T29: 위생도기 | U29: 변상익
A30: (주)대우건설 | B30: 대우건설 영종A9 후분양 현장(자체사업,APT)(1차 납품) | C30: 세광도기 | D30: '2026.04 | E30: '2026.05 | F30: CC740 | H30: 1100 | I30: 300 | J30: 158600 | K30: 36 | L30: =IFERROR(K30*H30,"0") -> 39600 | M30: =IFERROR(L30/1000,"0") -> 39.6 | N30: =J30*H30 -> 174460000 | O30: =I30*J30 -> 47580000 | Q30: 부속(대소구분레버),신형정심후렌지(202VN)1EA,앵글밸브1EA포함/시트제외 | R30: 김정완 | S30: 치마형투피스 | T30: 위생도기 | U30: 김주석
A31: 대우건설 | B31: 평택 푸르지오 센터파인(1차 납품) | C31: 세광도기 | D31: '2026.05 | E31: '2026.06 | F31: CC740 | H31: 800 | I31: 800 | J31: 146541 | K31: 36.4 | L31: =IFERROR(K31*H31,"0") -> 29120 | M31: =IFERROR(L31/1000,"0") -> 29.12 | N31: =J31*H31 -> 117232800 | O31: =I31*J31 -> 117232800 | R31: 김정완 | S31: 치마형투피스 | T31: 위생도기 | U31: 박기진
A32: 대우건설 | B32: 평택 푸르지오 센터파인(막차 납품) | C32: 세광도기 | D32: '2026.06 | E32: '2026.07 | F32: CC740 | H32: 808 | I32: 808 | J32: 146541 | K32: 36.4 | L32: =IFERROR(K32*H32,"0") -> 29411.2 | M32: =IFERROR(L32/1000,"0") -> 29.4112 | N32: =J32*H32 -> 118405128 | O32: =I32*J32 -> 118405128 | R32: 김정완 | S32: 치마형투피스 | T32: 위생도기 | U32: 박기진
A33: 코오롱건설 | B33: 권선6구역 래미안 매교역 팰루시드(1차 납품) | C33: 홈센타홀딩스 | D33: '2026.03 | E33: '2026.04 | F33: CLR358 | H33: 600 | I33: 405 | J33: 90400 | K33: 21 | L33: =IFERROR(K33*H33,"0") -> 12600 | M33: =IFERROR(L33/1000,"0") -> 12.6 | N33: =J33*H33 -> 54240000 | O33: =I33*J33 -> 36612000 | R33: 조동욱 | S33: 일체형세면기 | T33: 위생도기 | U33: 박기진
A34: 코오롱건설 | B34: 권선6구역 래미안 매교역 팰루시드(막차 납품) | C34: 홈센타홀딩스 | D34: '2026.04 | E34: '2026.04 | F34: CC660NLT | H34: 423 | I34: 391 | J34: 158000 | K34: 27 | L34: =IFERROR(K34*H34,"0") -> 11421 | M34: =IFERROR(L34/1000,"0") -> 11.421 | N34: =J34*H34 -> 66834000 | O34: =I34*J34 -> 61778000 | R34: 조동욱 | S34: 일체형양변기 | T34: 위생도기 | U34: 박기진
A35: 코오롱건설 | B35: 권선6구역 래미안 매교역 팰루시드(막차 납품) | C35: 홈센타홀딩스 | D35: '2026.04 | E35: '2026.04 | F35: CC750 | H35: 235 | I35: 195 | J35: 140980 | K35: 20 | L35: =IFERROR(K35*H35,"0") -> 4700 | M35: =IFERROR(L35/1000,"0") -> 4.7 | N35: =J35*H35 -> 33130300 | O35: =I35*J35 -> 27491100 | R35: 조동욱 | S35: 투피스 | T35: 위생도기 | U35: 박기진
A36: 삼성물산 | B36: 권선6구역 래미안 매교역 팰루시드(막차 납품) | C36: 케이씨씨글라스 | D36: '2026.03 | E36: '2026.04 | F36: CC660NLT | H36: 554 | I36: 426 | J36: 157944 | K36: 27 | L36: =IFERROR(K36*H36,"0") -> 14958 | M36: =IFERROR(L36/1000,"0") -> 14.958 | N36: =J36*H36 -> 87500976 | O36: =I36*J36 -> 67284144 | R36: 금지현 | S36: 일체형양변기 | T36: 위생도기 | U36: 조재민
A37: 삼성물산 | B37: 권선6구역 래미안 매교역 팰루시드(막차 납품) | C37: 케이씨씨글라스 | D37: '2026.03 | E37: '2026.04 | F37: CC750 | H37: 344 | I37: 304 | J37: 130011 | K37: 20 | L37: =IFERROR(K37*H37,"0") -> 6880 | M37: =IFERROR(L37/1000,"0") -> 6.88 | N37: =J37*H37 -> 44723784 | O37: =I37*J37 -> 39523344 | R37: 금지현 | S37: 투피스 | T37: 위생도기 | U37: 조재민
A38: 현대건설 | B38: 힐스테이트 마포더퍼스트 | C38: 직납 | D38: '2026.03 | E38: '2026.04 | F38: CL350D | H38: 1022 | I38: 522 | J38: 76279 | K38: 20 | L38: =IFERROR(K38*H38,"0") -> 20440 | M38: =IFERROR(L38/1000,"0") -> 20.44 | N38: =J38*H38 -> 77957138 | O38: =I38*J38 -> 39817638 | R38: 김광제 | S38: 일체형세면기 | T38: 위생도기 | U38: 박성진
A39: 리노공업 | B39: 부산 에코델타시티 일반산업단지 공장 신축공사 현장_비주거 | C39: 지얼세라믹 | D39: '2026.04 | E39: '2026.06 | F39: DL-L8210 | H39: 161 | I39: 157 | J39: 101503 | K39: 0 | L39: =IFERROR(K39*H39,"0") -> 0 | M39: =IFERROR(L39/1000,"0") -> 0 | N39: =J39*H39 -> 16341983 | O39: =I39*J39 -> 15935971 | R39: 김세동 | S39: 세면수전 | T39: 수전 | U39: 윤영재
A40: 리노공업 | B40: 부산 에코델타시티 일반산업단지 공장 신축공사 현장_비주거 | C40: 지얼세라믹 | D40: '2026.04 | E40: '2026.06 | F40: CL855 | H40: 156 | I40: 152 | J40: 55000 | K40: 17 | L40: =IFERROR(K40*H40,"0") -> 2652 | M40: =IFERROR(L40/1000,"0") -> 2.652 | N40: =J40*H40 -> 8580000 | O40: =I40*J40 -> 8360000 | R40: 김세동 | S40: 탑볼 | T40: OEM | U40: 윤영재
...

Sheet 2026정상완료
A1: 2026년 납품 완료 | C1: 1000000
D2: '2026.01 | E2: '2026.02 | F2: '2026.03 | G2: '2026.04 | H2: '2026.05 | I2: '2026.06 | J2: '2026.07 | K2: '2026.08 | L2: '2026.09 | M2: '2026.10 | N2: '2026.11 | O2: '2026.12 | P2: 합계
C3: 합계 | D3: =SUM(D4:D8) -> 6.4305977e+09 | E3: =SUM(E4:E8) -> 6.1320412e+09 | F3: =SUM(F4:F8) -> 4.249774e+09 | G3: =SUM(G4:G8) -> 0 | H3: =SUM(H4:H8) -> 0 | I3: =SUM(I4:I8) -> 0 | J3: =SUM(J4:J8) -> 0 | K3: =SUM(K4:K8) -> 0 | ... O3: =SUM(O4:O8) -> 0 | P3: =SUM(D3:O3) -> 16812412951
C4: 위생도기 | D4: =SUMIFS($M$10:$M$9118,$R$10:$R$9118,$C4,$D$10:$D$9118,D2) -> 2755189210 | E4: =SUMIFS($M$10:$M$9118,$R$10:$R$9118,$C$4,$D$10:$D$9118,E2) -> 3.1720439e+09 | F4: =SUMIFS($M$10:$M$9118,$R$10:$R$9118,$C$4,$D$10:$D$9118,F2) -> 2066569327 | G4: =SUMIFS($M$10:$M$9118,$R$10:$R$9118,$C$4,$D$10:$D$9118,G2) -> 0 | H4: =SUMIFS($M$10:$M$9118,$R$10:$R$9118,$C$4,$D$10:$D$9118,H2) -> 0 | I4: =SUMIFS($M$10:$M$9118,$R$10:$R$9118,$C$4,$D$10:$D$9118,I2) -> 0 | J4: =SUMIFS($M$10:$M$9118,$R$10:$R$9118,$C$4,$D$10:$D$9118,J2) -> 0 | K4: =SUMIFS($M$10:$M$9118,$R$10:$R$9118,$C$4,$D$10:$D$9118,K2) -> 0 | L4: =SUMIFS($M$10:$M$9118,$R$10:$R$9118,$C$4,$D$10:$D$9118,L2) -> 0 | ... O4: =SUMIFS($M$10:$M$9118,$R$10:$R$9118,$C$4,$D$10:$D$9118,O2) -> 0 | P4: =SUM(D4:O4) -> 7.9938025e+09
C5: OEM | D5: =SUMIFS($M$10:$M$9118,$R$10:$R$9118,$C5,$D$10:$D$9118,D$2) -> 5.2427663e+08 | E5: =SUMIFS($M$10:$M$9118,$R$10:$R$9118,$C5,$D$10:$D$9118,E$2) -> 8.4865219e+08 | F5: =SUMIFS($M$10:$M$9118,$R$10:$R$9118,$C5,$D$10:$D$9118,F$2) -> 4.5116352e+08 | G5: =SUMIFS($M$10:$M$9118,$R$10:$R$9118,$C5,$D$10:$D$9118,G$2) -> 0 | H5: =SUMIFS($M$10:$M$9118,$R$10:$R$9118,$C5,$D$10:$D$9118,H$2) -> 0 | I5: =SUMIFS($M$10:$M$9118,$R$10:$R$9118,$C5,$D$10:$D$9118,I$2) -> 0 | J5: =SUMIFS($M$10:$M$9118,$R$10:$R$9118,$C5,$D$10:$D$9118,J$2) -> 0 | K5: =SUMIFS($M$10:$M$9118,$R$10:$R$9118,$C5,$D$10:$D$9118,K$2) -> 0 | ... O5: =SUMIFS($M$10:$M$9118,$R$10:$R$9118,$C5,$D$10:$D$9118,O$2) -> 0 | P5: =SUM(D5:O5) -> 1.8240923e+09
C6: 상품 | D6: =SUMIFS($M$10:$M$9118,$R$10:$R$9118,$C6,$D$10:$D$9118,D$2) -> 586295658 | E6: =SUMIFS($M$10:$M$9118,$R$10:$R$9118,$C6,$D$10:$D$9118,E$2) -> 104762282 | F6: =SUMIFS($M$10:$M$9118,$R$10:$R$9118,$C6,$D$10:$D$9118,F$2) -> 131642839 | G6: =SUMIFS($M$10:$M$9118,$R$10:$R$9118,$C6,$D$10:$D$9118,G$2) -> 0 | H6: =SUMIFS($M$10:$M$9118,$R$10:$R$9118,$C6,$D$10:$D$9118,H$2) -> 0 | I6: =SUMIFS($M$10:$M$9118,$R$10:$R$9118,$C6,$D$10:$D$9118,I$2) -> 0 | J6: =SUMIFS($M$10:$M$9118,$R$10:$R$9118,$C6,$D$10:$D$9118,J$2) -> 0 | K6: =SUMIFS($M$10:$M$9118,$R$10:$R$9118,$C6,$D$10:$D$9118,K$2) -> 0 | L6: =SUMIFS($M$10:$M$9118,$R$10:$R$9118,$C6,$D$10:$D$9118,L$2) -> 0 | M6: =SUMIFS($M$10:$M$9118,$R$10:$R$9118,$C6,$D$10:$D$9118,M$2)+((M5+M4)*0.2) -> 0 | N6: =SUMIFS($M$10:$M$9118,$R$10:$R$9118,$C6,$D$10:$D$9118,N$2)+((N5+N4)*0.2) -> 0 | O6: =SUMIFS($M$10:$M$9118,$R$10:$R$9118,$C6,$D$10:$D$9118,O$2) -> 0 | P6: =SUM(D6:O6) -> 822700779
C7: 수전 | D7: =SUMIFS($M$10:$M$9118,$R$10:$R$9118,$C7,$D$10:$D$9118,D$2) -> 2.0745036e+09 | E7: =SUMIFS($M$10:$M$9118,$R$10:$R$9118,$C7,$D$10:$D$9118,E$2) -> 1.342604e+09 | F7: =SUMIFS($M$10:$M$9118,$R$10:$R$9118,$C7,$D$10:$D$9118,F$2) -> 1.4320494e+09 | G7: =SUMIFS($M$10:$M$9118,$R$10:$R$9118,$C7,$D$10:$D$9118,G$2) -> 0 | H7: =SUMIFS($M$10:$M$9118,$R$10:$R$9118,$C7,$D$10:$D$9118,H$2) -> 0 | I7: =SUMIFS($M$10:$M$9118,$R$10:$R$9118,$C7,$D$10:$D$9118,I$2) -> 0 | J7: =SUMIFS($M$10:$M$9118,$R$10:$R$9118,$C7,$D$10:$D$9118,J$2) -> 0 | K7: =SUMIFS($M$10:$M$9118,$R$10:$R$9118,$C7,$D$10:$D$9118,K$2) -> 0 | ... O7: =SUMIFS($M$10:$M$9118,$R$10:$R$9118,$C7,$D$10:$D$9118,O$2) -> 0 | P7: =SUM(D7:O7) -> 4.849157e+09
C8: 비데 | D8: =SUMIFS($M$10:$M$9118,$R$10:$R$9118,$C8,$D$10:$D$9118,D$2) -> 490332657 | E8: =SUMIFS($M$10:$M$9118,$R$10:$R$9118,$C8,$D$10:$D$9118,E$2) -> 6.6397883e+08 | F8: =SUMIFS($M$10:$M$9118,$R$10:$R$9118,$C8,$D$10:$D$9118,F$2) -> 168348913 | G8: =SUMIFS($M$10:$M$9118,$R$10:$R$9118,$C8,$D$10:$D$9118,G$2) -> 0 | H8: =SUMIFS($M$10:$M$9118,$R$10:$R$9118,$C8,$D$10:$D$9118,H$2) -> 0 | I8: =SUMIFS($M$10:$M$9118,$R$10:$R$9118,$C8,$D$10:$D$9118,I$2) -> 0 | J8: =SUMIFS($M$10:$M$9118,$R$10:$R$9118,$C8,$D$10:$D$9118,J$2) -> 0 | K8: =SUMIFS($M$10:$M$9118,$R$10:$R$9118,$C8,$D$10:$D$9118,K$2) -> 0 | ... O8: =SUMIFS($M$10:$M$9118,$R$10:$R$9118,$C8,$D$10:$D$9118,O$2) -> 0 | P8: =SUM(D8:O8) -> 1.3226604e+09
S9: (단위 : EA,원)
A10: 건설회사 | B10: 현장명 | C10: 대리점 | D10: 납품완료월 | E10: 기존 납품월 | F10: 품목 | G10: 색상 | H10: 수량 | I10: 단가 | J10: 중량(KG) | K10: 총무게(KG) | L10: 총(TON) | M10: 금액 | N10: 특수사양 | O10: 비고 | P10: 담당자 | Q10: 품목 | R10: 구분 | S10: SPEC담당
A11: 현대건설 | B11: 청라 하나드림타워 HQ현장(1차 납품) | C11: 직납 | D11: '2026.01 | E11: '2025.12 | F11: CU511PUJ | H11: 60 | I11: 181402 | J11: 40 | K11: =IFERROR(J11*H11,"0") -> 2400 | L11: =IFERROR(K11/1000,"0") -> 2.4 | M11: =H11*I11 -> 10884120 | O11: 전기식 | P11: 김광제 | Q11: 소변기 | R11: OEM | S11: 박성진
A12: 태왕이앤씨 | B12: 대구 태왕아너스 프리미어(성창 재건축)(1차 납품) | C12: 홈센타홀딩스 | D12: '2026.01 | E12: '2026.01 | F12: CC728 | H12: 200 | I12: 101600 | J12: 41 | K12: =IFERROR(J12*H12,"0") -> 8200 | L12: =IFERROR(K12/1000,"0") -> 8.2 | M12: =I12*H12 -> 20320000 | P12: 강승근 | Q12: 치마형투피스 | R12: OEM | S12: 최윤한
A13: 태왕이앤씨 | B13: 대구 태왕아너스 프리미어(성창 재건축)(1차 납품) | C13: 홈센타홀딩스 | D13: '2026.01 | E13: '2026.01 | F13: CL336D | H13: 200 | I13: 49700 | J13: 15.5 | K13: =IFERROR(J13*H13,"0") -> 3100 | L13: =IFERROR(K13/1000,"0") -> 3.1 | M13: =I13*H13 -> 9940000 | P13: 강승근 | Q13: 벽붙이세면기 | R13: 위생도기 | S13: 최윤한
A14: 태왕이앤씨 | B14: 대구 태왕아너스 프리미어(성창 재건축)(1차 납품) | C14: 홈센타홀딩스 | D14: '2026.01 | E14: '2026.01 | F14: DL-L5510 | H14: 200 | I14: 41800 | J14: 0 | K14: =IFERROR(J14*H14,"0") -> 0 | L14: =IFERROR(K14/1000,"0") -> 0 | M14: =I14*H14 -> 8360000 | P14: 강승근 | Q14: 세면수전 | R14: 수전 | S14: 최윤한
A15: 태왕이앤씨 | B15: 대구 태왕아너스 프리미어(성창 재건축)(1차 납품) | C15: 홈센타홀딩스 | D15: '2026.01 | E15: '2026.01 | F15: DL-G4541C | H15: 100 | I15: 7800 | J15: 0 | K15: =IFERROR(J15*H15,"0") -> 0 | L15: =IFERROR(K15/1000,"0") -> 0 | M15: =I15*H15 -> 780000 | P15: 강승근 | Q15: 가로꼭지 | R15: 수전 | S15: 최윤한
A16: 태왕이앤씨 | B16: 대구 태왕아너스 프리미어(성창 재건축)(1차 납품) | C16: 홈센타홀딩스 | D16: '2026.01 | E16: '2026.01 | F16: DL-G4543C | H16: 100 | I16: 6500 | J16: 0 | K16: =IFERROR(J16*H16,"0") -> 0 | L16: =IFERROR(K16/1000,"0") -> 0 | M16: =I16*H16 -> 650000 | P16: 강승근 | Q16: 가로꼭지 | R16: 수전 | S16: 최윤한
A17: 태왕이앤씨 | B17: 대구 태왕아너스 프리미어(성창 재건축)(1차 납품) | C17: 홈센타홀딩스 | D17: '2026.01 | E17: '2026.01 | F17: DL-G4543H | H17: 100 | I17: 6500 | J17: 0 | K17: =IFERROR(J17*H17,"0") -> 0 | L17: =IFERROR(K17/1000,"0") -> 0 | M17: =I17*H17 -> 650000 | P17: 강승근 | Q17: 가로꼭지 | R17: 수전 | S17: 최윤한
A18: 태왕이앤씨 | B18: 대구 태왕아너스 프리미어(성창 재건축)(1차 납품) | C18: 홈센타홀딩스 | D18: '2026.01 | E18: '2026.01 | F18: DL-G4545C | H18: 100 | I18: 6100 | J18: 0 | K18: =IFERROR(J18*H18,"0") -> 0 | L18: =IFERROR(K18/1000,"0") -> 0 | M18: =I18*H18 -> 610000 | P18: 강승근 | Q18: 가로꼭지 | R18: 수전 | S18: 최윤한
A19: 태왕이앤씨 | B19: 대구 태왕아너스 프리미어(성창 재건축)(1차 납품) | C19: 홈센타홀딩스 | D19: '2026.01 | E19: '2026.01 | F19: DL-G4545H | H19: 100 | I19: 6100 | J19: 0 | K19: =IFERROR(J19*H19,"0") -> 0 | L19: =IFERROR(K19/1000,"0") -> 0 | M19: =I19*H19 -> 610000 | P19: 강승근 | Q19: 가로꼭지 | R19: 수전 | S19: 최윤한
A20: 태왕이앤씨 | B20: 대구 태왕아너스 프리미어(성창 재건축)(1차 납품) | C20: 홈센타홀딩스 | D20: '2026.01 | E20: '2026.01 | F20: DL-P4202 | H20: 100 | I20: 4100 | J20: 0 | K20: =IFERROR(J20*H20,"0") -> 0 | L20: =IFERROR(K20/1000,"0") -> 0 | M20: =I20*H20 -> 410000 | P20: 강승근 | Q20: 기타수전 | R20: 수전 | S20: 최윤한
A21: 태왕이앤씨 | B21: 대구 태왕아너스 프리미어(성창 재건축)(1차 납품) | C21: 홈센타홀딩스 | D21: '2026.01 | E21: '2026.01 | F21: DL-S4195 | H21: 100 | I21: 6300 | J21: 0 | K21: =IFERROR(J21*H21,"0") -> 0 | L21: =IFERROR(K21/1000,"0") -> 0 | M21: =I21*H21 -> 630000 | P21: 강승근 | Q21: 스프레이건 | R21: 수전 | S21: 최윤한
A22: 태왕이앤씨 | B22: 대구 태왕아너스 프리미어(성창 재건축)(1차 납품) | C22: 홈센타홀딩스 | D22: '2026.01 | E22: '2026.01 | F22: DL-P4014 | H22: 100 | I22: 18000 | J22: 0 | K22: =IFERROR(J22*H22,"0") -> 0 | L22: =IFERROR(K22/1000,"0") -> 0 | M22: =I22*H22 -> 1800000 | P22: 강승근 | Q22: 기타수전 | R22: 수전 | S22: 최윤한
A23: 태왕이앤씨 | B23: 대구 태왕아너스 프리미어(성창 재건축)(2차 납품) | C23: 홈센타홀딩스 | D23: '2026.01 | E23: '2026.01 | F23: CC728 | H23: 200 | I23: 101600 | J23: 41 | K23: =IFERROR(J23*H23,"0") -> 8200 | L23: =IFERROR(K23/1000,"0") -> 8.2 | M23: =I23*H23 -> 20320000 | P23: 강승근 | Q23: 치마형투피스 | R23: OEM | S23: 최윤한
... A60: 현대건설 | B60: 힐스테이트 마포더퍼스트 | C60: 직납 | D60: '2026.01 | E60: '2026.02 | F60: DL-P4010 | H60: 1022 | I60: 3255 | J60: 0 | K60: =IFERROR(J60*H60,"0") -> 0 | L60: =IFERROR(K60/1000,"0") -> 0 | M60: =I60*H60 -> 3326610 | P60: 김광제 | Q60: 기타수전 | R60: 수전 | S60: 박성진
A61: 현대건설 | B61: 인천 청라 드림타운(막차 납품) | C61: 직납 | D61: '2026.01 | E61: '2026.01 | F61: CC550PWFT | H61: 284 | I61: 265000 | J61: 28.2 | K61: =IFERROR(J61*H61,"0") -> 8008.8 | L61: =IFERROR(K61/1000,"0") -> 8.0088 | M61: =I61*H61 -> 75260000 | N61: 양변기 고압호스 +10CM | P61: 김광제 | Q61: 일체형양변기 | R61: 위생도기 | S61: 박성진
A62: 포스코건설 | B62: 오티에르 신반포(신반포18차 337동 재건축) | C62: 한일상사 | D62: '2026.01 | E62: '2026.01 | F62: CC670EKT | H62: 210 | I62: 153706 | J62: 29.3 | K62: =IFERROR(J62*H62,"0") -> 6153 | L62: =IFERROR(K62/1000,"0") -> 6.153 | M62: =I62*H62 -> 32278260 | P62: 김세동 | Q62: 일체형양변기 | R62: 위생도기 | S62: 변상익
A63: 포스코건설 | B63: 오티에르 신반포(신반포18차 337동 재건축) | C63: 한일상사 | D63: '2026.01 | E63: '2026.01 | F63: DL-P4010 | H63: 210 | I63: 2753 | J63: 0 | K63: =IFERROR(J63*H63,"0") -> 0 | L63: =IFERROR(K63/1000,"0") -> 0 | M63: =I63*H63 -> 578130 | P63: 김세동 | Q63: 기타수전 | R63: 수전 | S63: 변상익
